Workbook

Sheet US
A1: TIMELINE | B1: 2000-2030
A2: COUNTRY | B2: USA
A5: Notation | B5: Parameter Description | C5: Unit of Measure | D5: Max_Value | E5: Min_Value | F5: Distribution | G5: Source/Justification | H5: 36526 | I5: 36557 | J5: 36586 | K5: 36617 | L5: 36647 | M5: 36678 | N5: 36708 | O5: 36739 | P5: 36770 | Q5: 36800 | R5: 36831 | S5: 36861 | T5: 36892 | U5: 36923 | V5: 36951 | W5: 36982 | X5: 37012 | Y5: 37043 | Z5: 37073 | AA5: 37104 | AB5: 37135 | AC5: 37165 | AD5: 37196 | AE5: 37226 | AF5: 37257 | AG5: 37288 | AH5: 37316 | AI5: 37347 | AJ5: 37377 | AK5: 37408 | AL5: 37438 | AM5: 37469 | AN5: 37500 | AO5: 37530 | AP5: 37561 | AQ5: 37591 | AR5: 37622 | AS5: 37653 | AT5: 37681 | AU5: 37712 | AV5: 37742 | AW5: 37773 | AX5: 37803 | AY5: 37834 | AZ5: 37865 | BA5: 37895 | BB5: 37926 | BC5: 37956 | BD5: 37987 | BE5: 38018 | BF5: 38047 | BG5: 38078 | BH5: 38108 | BI5: 38139 | BJ5: 38169 | BK5: 38200 | BL5: 38231 | BM5: 38261 | BN5: 38292 | BO5: 38322 | BP5: 38353 | BQ5: 38384 | BR5: 38412 | BS5: 38443 | BT5: 38473 | BU5: 38504 | BV5: 38534 | BW5: 38565 | BX5: 38596 | BY5: 38626 | BZ5: 38657 | CA5: 38687 | CB5: 38718 | CC5: 38749 | CD5: 38777 | CE5: 38808 | CF5: 38838 | CG5: 38869 | CH5: 38899 | CI5: 38930 | CJ5: 38961 | CK5: 38991 | CL5: 39022 | CM5: 39052 | CN5: 39083 | CO5: 39114 | CP5: 39142 | CQ5: 39173 | CR5: 39203 | CS5: 39234 | CT5: 39264 | CU5: 39295 | CV5: 39326 | CW5: 39356 | CX5: 39387 | CY5: 39417 | CZ5: 39448 | DA5: 39479 | DB5: 39508 | DC5: 39539 | DD5: 39569 | DE5: 39600 | DF5: 39630 | DG5: 39661 | DH5: 39692 | DI5: 39722 | DJ5: 39753 | DK5: 39783 | DL5: 39814 | DM5: 39845 | DN5: 39873 | DO5: 39904 | DP5: 39934 | DQ5: 39965 | DR5: 39995 | DS5: 40026 | DT5: 40057 | DU5: 40087 | DV5: 40118 | DW5: 40148 | DX5: 40179 | DY5: 40210 | DZ5: 40238 | EA5: 40269 | EB5: 40299 | EC5: 40330 | ED5: 40360 | EE5: 40391 | EF5: 40422 | EG5: 40452 | EH5: 40483 | EI5: 40513 | EJ5: 40544 | EK5: 40575 | EL5: 40603 | EM5: 40634 | EN5: 40664 | EO5: 40695 | EP5: 40725 | EQ5: 40756 | ER5: 40787 | ES5: 40817 | ET5: 40848 | EU5: 40878 | EV5: 40909 | EW5: 40940 | EX5: 40969 | EY5: 41000 | EZ5: 41030 | FA5: 41061 | FB5: 41091 | FC5: 41122 | FD5: 41153 | FE5: 41183 | FF5: 41214 | FG5: 41244 | FH5: 41275 | FI5: 41306 | FJ5: 41334 | FK5: 41365 | FL5: 41395 | FM5: 41426 | FN5: 41456 | FO5: 41487 | FP5: 41518 | FQ5: 41548 | FR5: 41579 | FS5: 41609 | FT5: 41640 | FU5: 41671 | FV5: 41699 | FW5: 41730 | FX5: 41760 | FY5: 41791 | FZ5: 41821 | GA5: 41852 | GB5: 41883 | GC5: 41913 | GD5: 41944 | GE5: 41974 | GF5: 42005 | GG5: 42036 | GH5: 42064 | GI5: 42095 | GJ5: 42125 | GK5: 42156 | GL5: 42186 | GM5: 42217 | GN5: 42248 | GO5: 42278 | GP5: 42309 | GQ5: 42339 | GR5: 42370 | GS5: 42401 | GT5: 42430 | GU5: 42461 | GV5: 42491 | GW5: 42522 | GX5: 42552 | GY5: 42583 | GZ5: 42614 | HA5: 42644 | HB5: 42675 | HC5: 42705 | HD5: 42736 | HE5: 42767 | HF5: 42795 | HG5: 42826 | HH5: 42856 | HI5: 42887 | HJ5: 42917 | HK5: 42948 | HL5: 42979 | HM5: 43009 | HN5: 43040 | HO5: 43070 | HP5: 43101 | HQ5: 43132 | HR5: 43160 | HS5: 43191 | HT5: 43221 | HU5: 43252 | HV5: 43282 | HW5: 43313 | HX5: 43344 | HY5: 43374 | HZ5: 43405 | IA5: 43435 | IB5: 43466 | IC5: 43497 | ID5: 43525 | IE5: 43556 | IF5: 43586 | IG5: 43617 | IH5: 43647 | II5: 43678 | IJ5: 43709 | IK5: 43739 | IL5: 43770 | IM5: 43800 | IN5: 43831 | IO5: 43862 | IP5: 43891 | IQ5: 43922 | IR5: 43952 | IS5: 43983 | IT5: 44013 | IU5: 44044 | IV5: 44075 | IW5: 44105 | IX5: 44136 | IY5: 44166 | IZ5: 44197 | JA5: 44228 | JB5: 44256 | JC5: 44287 | JD5: 44317 | JE5: 44348 | JF5: 44378 | JG5: 44409 | JH5: 44440 | JI5: 44470 | JJ5: 44501 | JK5: 44531 | JL5: 44562 | JM5: 44593 | JN5: 44621 | JO5: 44652 | JP5: 44682 | JQ5: 44713 | JR5: 44743 | JS5: 44774 | JT5: 44805 | JU5: 44835 | JV5: 44866 | JW5: 44896 | JX5: 44927 | JY5: 44958 | JZ5: 44986 | KA5: 45017 | KB5: 45047 | KC5: 45078 | KD5: 45108 | KE5: 45139 | KF5: 45170 | KG5: 45200 | KH5: 45231 | KI5: 45261 | KJ5: 45292 | KK5: 45323 | KL5: 45352 | KM5: 45383 | KN5: 45413 | KO5: 45444 | KP5: 45474 | KQ5: 45505 | KR5: 45536 | KS5: 45566 | KT5: 45597
A6: C_m (ICE) | B6: ICE unit production costs | C6: Dollars / car | D6: 50000 | E6: 5000 | F6: NK | G6: In Grieco et al. (2024) we see that prices (of non-luxury cars) range from 15k to 50k from 1980 to 2020, while mark-ups range from 10 to 50%. This range of costs is consistent with that observation, allwoing for a 10% deviation due to further innovation.
A7: C_m (EV) | B7: EV unit production costs | C7: Dollars / car | D7: 50000 | E7: 5000 | F7: NK | G7: No reason to assume it is different for Evs.
A8: C_m (RPT) | B8: Monthly maintainance cost of rural public transport (rural areas within a district) | C8: Dollars / month | D8: =10^5 -> 100000 | E8: =10^6 -> 1000000 | F8: We could use multiple cities and rural circles and initialise to the case of the US; then make costs proportional to area population. | G8: Federal Support of Public Transportation Operating Expenses and https://www.apta.com/research-technical-resources/transit-statistics/public-transportation-fact-book/
A9: C_m (UPT) | B9: Monthly maintainance cost of urban public transport (of a city) | C9: Dollars / month | D9: =10^6 -> 1000000 | E9: =8*10^8 -> 800000000 | F9: We could use multiple cities and rural circles and initialise to the case of the US; then make costs proportional to area population. | G9: Federal Support of Public Transportation Operating Expenses and https://www.apta.com/research-technical-resources/transit-statistics/public-transportation-fact-book/
A10: c_m (gasoline) | B10: Gasoline cost per Kilowatt Hour | C10: $ / KwH | F10: Single value per fuel type | G10: https://www.eia.gov/petroleum/gasdiesel/ | H10: {=$B$54*INDEX('Gasoline and electricity'!$H$1:$I$413,MATCH(US!H$5,'Gasoline and electricity'!$I$1:$I$413,0),1)} -> 0.037946588 | I10: {=$B$54*INDEX('Gasoline and electricity'!$H$1:$I$413,MATCH(US!I$5,'Gasoline and electricity'!$I$1:$I$413,0),1)} -> 0.040667656 | J10: {=$B$54*INDEX('Gasoline and electricity'!$H$1:$I$413,MATCH(US!J$5,'Gasoline and electricity'!$I$1:$I$413,0),1)} -> 0.044458457 | K10: {=$B$54*INDEX('Gasoline and electricity'!$H$1:$I$413,MATCH(US!K$5,'Gasoline and electricity'!$I$1:$I$413,0),1)} -> 0.042626113 | L10: {=$B$54*INDEX('Gasoline and electricity'!$H$1:$I$413,MATCH(US!L$5,'Gasoline and electricity'!$I$1:$I$413,0),1)} -> 0.043216617 | M10: {=$B$54*INDEX('Gasoline and electricity'!$H$1:$I$413,MATCH(US!M$5,'Gasoline and electricity'!$I$1:$I$413,0),1)} -> 0.04782641 | N10: {=$B$54*INDEX('Gasoline and electricity'!$H$1:$I$413,MATCH(US!N$5,'Gasoline and electricity'!$I$1:$I$413,0),1)} -> 0.045364985 | O10: {=$B$54*INDEX('Gasoline and electricity'!$H$1:$I$413,MATCH(US!O$5,'Gasoline and electricity'!$I$1:$I$413,0),1)} -> 0.042707715 | ... KT10: {=$B$54*INDEX('Gasoline and electricity'!$H$1:$I$413,MATCH(US!KT$5,'Gasoline and electricity'!$I$1:$I$413,0),1)} -> 0.087903066
A11: c_m (electricity) | B11: Electricity cost (retail) per Kilowatt Hour | C11: $ / KwH | F11: Single value per fuel type | G11: https://fred.stlouisfed.org/series/APU000072610 | H11: {=INDEX('Gasoline and electricity'!$K$1:$L$553,MATCH(US!H$5,'Gasoline and electricity'!$K$1:$K$553,0),2)} -> 0.084 | I11: {=INDEX('Gasoline and electricity'!$K$1:$L$553,MATCH(US!I$5,'Gasoline and electricity'!$K$1:$K$553,0),2)} -> 0.085 | J11: {=INDEX('Gasoline and electricity'!$K$1:$L$553,MATCH(US!J$5,'Gasoline and electricity'!$K$1:$K$553,0),2)} -> 0.085 | K11: {=INDEX('Gasoline and electricity'!$K$1:$L$553,MATCH(US!K$5,'Gasoline and electricity'!$K$1:$K$553,0),2)} -> 0.085 | L11: {=INDEX('Gasoline and electricity'!$K$1:$L$553,MATCH(US!L$5,'Gasoline and electricity'!$K$1:$K$553,0),2)} -> 0.085 | M11: {=INDEX('Gasoline and electricity'!$K$1:$L$553,MATCH(US!M$5,'Gasoline and electricity'!$K$1:$K$553,0),2)} -> 0.09 | N11: {=INDEX('Gasoline and electricity'!$K$1:$L$553,MATCH(US!N$5,'Gasoline and electricity'!$K$1:$K$553,0),2)} -> 0.091 | O11: {=INDEX('Gasoline and electricity'!$K$1:$L$553,MATCH(US!O$5,'Gasoline and electricity'!$K$1:$K$553,0),2)} -> 0.091 | ... KT11: {=INDEX('Gasoline and electricity'!$K$1:$L$553,MATCH(US!KT$5,'Gasoline and electricity'!$K$1:$K$553,0),2)} -> #N/A
A12: d^-_i | B12: Minimum distance requirement | C12: Miles / month | D12: 200 | E12: 0 | F12: Matching the income sensitvity distribution (https://www.urban.org/features/unequal-commute) -> Should give an average within the range (150-175) | G12: The 2017 National Household Travel Survey reports an average of 175 to 150 vehicle miles traveled weekly for work and shopping; it also reports inequality on the work/residence mismatch, so we account for it by replicating the distribution
A13: d^G_z (urban) | B13: Travelled distance of urban public transportation | C13: Miles / month | D13: 1500 | E13: 830 | F13: We could use multiple cities and rural circles and initialise to the case of the US; then make costs proportional to area population. | G13: https://www.transit.dot.gov/ntd/data-product/monthly-module-raw-data-release
A14: d^G_z (rural) | B14: Travelled distance of rural public transportation | C14: Miles / month | D14: 40000 | E14: =10^6 -> 1000000 | F14: We could use multiple cities and rural circles and initialise to the case of the US; then make costs proportional to area population. | G14: https://www.transit.dot.gov/ntd/data-product/monthly-module-raw-data-release
A15: E_m (EV) | B15: Technology production emissions (EV) | C15: Kilograms of CO2 / car | D15: =(5.4+1.2+1.8)*1000 -> 8400 | E15: =(5.4+1.2+2.8)*1000 -> 9400 | F15: Single value for the entire NK, these are just scenarios of GHG minerals | G15: https://www.iea.org/data-and-statistics/charts/comparative-life-cycle-greenhouse-gas-emissions-of-a-mid-size-bev-and-ice-vehicle
A16: E_m (ICE) | B16: Technology production emissions (ICE) | C16: Kilograms of CO2 / car | D16: 6000 | E16: 6000 | F16: NK | G16: https://www.iea.org/data-and-statistics/charts/comparative-life-cycle-greenhouse-gas-emissions-of-a-mid-size-bev-and-ice-vehicle
A17: e_m (gasoline) | B17: Fuel emissions per KWh | C17: Kilograms of CO2 / KWh | D17: =8.887*B54 -> 0.2637092 | E17: =D17 -> 0.2637092 | F17: Single value per fuel type | G17: https://www.epa.gov/greenvehicles/greenhouse-gas-emissions-typical-passenger-vehicle
A18: e_m (electricity) | B18: Electricity emsissions per KWh | C18: Kilograms of CO2 / KWh | D18: ='Electricity emissions'!A36*'Electricity emissions'!B38 -> 0.37335188 | E18: =D18 -> 0.37335188 | F18: Single value per fuel type | G18: https://www.epa.gov/egrid/summary-data
A19: O_i (rural) | B19: Individual place of residence | C19: Binary (0=rural, 1=urban) | D19: 0.2 | E19: 0.2 | F19: Single value per origin type | G19: https://www.census.gov/newsroom/press-releases/2022/urban-rural-populations.html
A20: O_i (urban) | B20: Individual place of residence | C20: Binary (0=rural, 1=urban) | D20: 0.8 | E20: 0.8 | F20: Single value per origin type | G20: https://www.census.gov/newsroom/press-releases/2022/urban-rural-populations.html
A21: P^G_z | B21: Monthly ticket fare of public transportation z (urban) | C21: Dolars / month | D21: 40 | E21: 70 | F21: APTA Annual Public Transportation Fact Book
A22: P^G_z | B22: Monthly ticket fare of public transportation z (rural) | C22: Dolars / month | E22: 20 | F22: APTA Annual Public Transportation Fact Book
A23: Q_m | B23: Vehicle quality | C23: Utility / kilometre | D23: (if beta is 0 then you dont care about price, price is all relative) CALIBRATE S.T. SOMEONE WITH BETA=0 and GAMMA=0 would be willing to pay 50 to 100k for a new car | G23: This has to be calibrated in such way that a person with no carbon or price sensitivity should be willing to pay around 80-50k for a new car (average price of a high-range non-luxury car)
A24: r | B24: Discount rate | C24: Percent | D24: 0 | E24: 0.05 | F24: We can just follow the trend of the 1-year Treasury bond | G24: https://fred.stlouisfed.org/series/DGS1/#0 | H24: What is the idea behind this discount rate?
A25: T^+ | B25: Time limit for unsold used cars | C25: Months | D25: 1 | E25: 2 | F25: Just pick-up a value | G25: NADA (National Automobile Dealers Association) reports average used car inventory holding time of 52 days https://www.nada.org/media/4694/download?inline
A26: α | B26: Utility scale of returns to distance travelled | C26: Scale | D26: INDIRECT CALIBRATION | F26: Global param
A27: β_i | B27: Individual price sensitivity | C27: Utility / Monetary units | D27: INDIRECT CALIBRATION | F27: Try to match income distribution for this distribution
A28: β_s | B28: Segment price sensitivity | C28: Utility / Monetary units | D28: In-segment average
A29: β̂ | B29: High income threshold | C29: Utility / Monetary units | D29: Set at the equivalent of what is considered the high-income tier
A30: γ_i | B30: Individual environmental awareness | C30: Utility / Kilograms of CO2 | D30: INDIRECT CALIBRATION
A31: γ_s | B31: Segment environmental awareness | C31: Utility / Kilograms of CO2 | D31: In-segment average
A32: γ̂ | B32: Environmental awareness threshold | C32: Utility / Kilograms of CO2 | D32: Set at average
A33: δ_z | B33: Depreciation rate | C33: Percent | D33: 0.01 | E33: 0.03 | F33: CALIBRATE TO MATCH VEHICLE AGE
A34: η | B34: Time sensitivity | C34: Utility / Hours | D34: INDIRECT CALIBRATION
A35: ι | B35: Probability of successful innovation | C35: Percent | D35: 45627
A36: κ | B36: Intensity of competition | C36: Scale | D36: INDIRECT CALIBRATION, or maybe just get from the discrete choice models out there
A37: λ | B37: Rate of exploitation in firm search | C37: Scale | D37: Copy from papers on managerial sciences about optimal rates of exploration/exploitation
A38: μ | B38: Used car dealer mark-up (This is the discount on the original price not the markup) | C38: Percent | D38: 0.3
A39: ν_i | B39: Average time spent travelling | C39: Hours / Kilometre | D39: ???
A40: ρ_{f,z} | B40: Attribute f correlation w.r.t attribute f=0 | C40: [-1,1] | D40: [1,.5,0]
A41: χ_i | B41: Adoption threshold | C41: Percent | D41: Get from that nice paper
A42: ω_m | B42: Fuel efficiency (EV) (should be in km) | C42: km / KWh | D42: 4 | E42: 7 | F42: https://www.fueleconomy.gov/feg/PowerSearch.do?action=Cars&vtype=Electric&srchtyp=evSelect&rowLimit=50&sortBy=Comb&year1=2006&year2=2011&mclass=Small%20Cars,Coupes,Sports/Sporty%20Cars,Hatchbacks,Family%20Sedans,Upscale%20Sedans,Luxury%20Sedans,Sport%20Utility%20Vehicles&range=&drive=
...

Sheet outputs
A1: Notation | B1: Parameter Description | C1: Unit of Measure | D1: Max_Value | E1: Min_Value | F1: Distribution | G1: Source/Justification
A2: Total emissions
A3: Ev uptake
A4: Km/Mile | B4: 1.609
A7: Output variable | B7: 2000 | C7: 2001 | D7: 2002 | E7: 2003 | F7: 2004 | G7: 2005 | H7: 2006 | I7: 2007 | J7: 2008 | K7: 2009 | L7: 2010 | M7: 2011 | N7: 2012 | O7: 2013 | P7: 2014 | Q7: 2015 | R7: 2016 | S7: 2017 | T7: 2018 | U7: 2019 | V7: 2020 | W7: 2021 | X7: 2022 | Y7: 2023 | Z7: 2024 | AA7: Source/Justificaiton
A8: Transit Ridership (I don't know the measure) | B8: 1,311,824,696.00 | C8: 1,346,517,005.00 | D8: 1,377,987,092.00 | E8: 1,327,293,349.00 | F8: 1,294,728,947.00 | G8: 1,357,675,691.00 | H8: 1,406,095,938.00 | I8: 1,441,805,116.00 | J8: 1,459,165,411.00 | K8: 1,474,373,826.00 | L8: 1,403,504,000.00 | M8: 1,386,899,775.00 | N8: 1,418,917,723.00 | O8: 1,441,811,356.00 | P8: 1,458,600,707.00 | Q8: 1,435,297,360.00 | R8: 1,398,152,646.00 | S8: 1,324,436,440.00 | T8: 1,293,074,046.00 | U8: 1,267,399,653.00 | V8: 1,000,292,915.00 | W8: 489,444,294.00 | X8: 705,670,207.00 | AA8: https://www.bts.gov/browse-statistical-products-and-data/state-transportation-statistics/state-highway-travel
A9: Highway use of gasoline (thousand gallons) | B9: 14,378,254.00 | C9: 14,691,753.00 | D9: 15,385,840.00 | E9: 15,358,354.00 | F9: 15,579,476.00 | G9: 15,614,464.00 | H9: 15,509,940.00 | I9: 15,402,164.00 | J9: 14,787,997.00 | K9: 14,575,049.00 | L9: 14,555,037.00 | M9: 14,276,055.00 | N9: 14,221,198.00 | O9: 14,201,939.00 | P9: 14,660,111.00 | Q9: 14,188,342.00 | R9: 14,540,213.00 | S9: 14,613,569.00 | T9: 14,536,101.00 | U9: 14,432,583.00 | V9: 11,487,227.00 | W9: 12,812,146.00 | X9: 12,516,732.00 | AA9: https://www.bts.gov/browse-statistical-products-and-data/state-transportation-statistics/state-highway-travel
A10: Highway vehicle-miles traveled (millions) | B10: 306,649.00 | C10: 310,575.00 | D10: 320,942.00 | E10: 323,592.00 | F10: 328,917.00 | G10: 329,267.00 | H10: 327,478.00 | I10: 328,312.00 | J10: 327,286.00 | K10: 324,486.00 | L10: 322,849.40 | M10: 320,783.91 | N10: 326,271.65 | O10: 329,534.13 | P10: 332,857.20 | Q10: 335,538.56 | R10: 340,115.00 | S10: 343,862.11 | T10: 348,795.71 | U10: 340,836.25 | V10: 299,811.68 | W10: 310,822.73 | X10: 315,243.57 | AA10: https://www.bts.gov/browse-statistical-products-and-data/state-transportation-statistics/state-highway-travel
A11: Vehicles | B11: 27,697,920.00 | C11: 28,780,060.00 | D11: 29,618,610.00 | E11: 30,248,070.00 | F11: 31,399,600.00 | G11: 32,487,480.00 | H11: 33,182,060.00 | I11: 33,935,390.00 | J11: 33,483,060.00 | K11: 34,433,210.00 | L11: 31,014,130.00 | M11: 29,176,700.00 | N11: 27,702,150.00 | O11: 28,074,980.00 | P11: 28,686,650.00 | Q11: 29,424,012.00 | R11: 30,221,033.00 | S11: 30,795,141.00 | T11: 31,022,328.00 | U11: 31,247,270.05 | V11: 30,398,249.00 | W11: 31,349,073.00 | X11: 31,119,113.00 | AA11: https://www.bts.gov/browse-statistical-products-and-data/state-transportation-statistics/state-highway-travel
A12: Licensed drivers | B12: 21,243,939.00 | C12: 21,623,793.00 | D12: 22,394,800.00 | E12: 22,657,288.00 | F12: 22,761,088.00 | G12: 22,895,965.00 | H12: 23,021,279.00 | I12: 23,467,452.00 | J12: 23,697,667.00 | K12: 23,680,643.00 | L12: 23,753,441.00 | M12: 23,856,600.00 | N12: 24,200,997.00 | O12: 24,390,236.00 | P12: 24,813,346.00 | Q12: 25,532,920.00 | R12: 26,199,436.00 | S12: 26,777,132.00 | T12: 27,039,400.00 | U12: 27,213,650.00 | V12: 27,005,302.00 | W12: 27,112,595.00 | X12: 27,632,103.00 | Z12: 1586413 | AA12: https://www.bts.gov/browse-statistical-products-and-data/state-transportation-statistics/state-highway-travel
A13: Vehicle-to-driver ratio | B13: =B11/B12 -> 1.3038034 | C13: =C11/C12 -> 1.3309441 | D13: =D11/D12 -> 1.3225664 | E13: =E11/E12 -> 1.3350261 | F13: =F11/F12 -> 1.3795298 | G13: =G11/G12 -> 1.4189173 | H13: =H11/H12 -> 1.4413647 | I13: =I11/I12 -> 1.446062 | ... X13: =X11/X12 -> 1.1261942 | Z13: =Z12/X12 -> 0.057411953
A14: Ridership per vehicle | B14: =B8/B$11 -> 47.361849 | C14: =C8/C$11 -> 46.786456 | D14: =D8/D$11 -> 46.524367 | E14: =E8/E$11 -> 43.880266 | F14: =F8/F$11 -> 41.233931 | G14: =G8/G$11 -> 41.790736 | H14: =H8/H$11 -> 42.375185 | I14: =I8/I$11 -> 42.48677 | ... X14: =X8/X$11 -> 22.676424 | Z14: =Z13/12 -> 0.0047843294
A15: Gasoline per vehicle (gallons) | B15: =1000*B9/B$11 -> 519.10952 | C15: =1000*C9/C$11 -> 510.48375 | D15: =1000*D9/D$11 -> 519.4653 | E15: =1000*E9/E$11 -> 507.74658 | F15: =1000*F9/F$11 -> 496.16798 | G15: =1000*G9/G$11 -> 480.6302 | H15: =1000*H9/H$11 -> 467.41944 | I15: =1000*I9/I$11 -> 453.8673 | ... X15: =1000*X9/X$11 -> 402.22008
A16: Distance per vehicle (miles) | B16: =10^6*B10/B$11 -> 11071.192 | C16: =10^6*C10/C$11 -> 10791.326 | D16: =10^6*D10/D$11 -> 10835.822 | E16: =10^6*E10/E$11 -> 10697.939 | F16: =10^6*F10/F$11 -> 10475.197 | G16: =10^6*G10/G$11 -> 10135.197 | H16: =10^6*H10/H$11 -> 9869.1281 | I16: =10^6*I10/I$11 -> 9674.6199 | ... X16: =10^6*X10/X$11 -> 10130.224
A17: Distance per vehicle (km/Month) | B17: =$B$4*B16/12 -> 1484.4624 | C17: =$B$4*C16/12 -> 1446.9369 | D17: =$B$4*D16/12 -> 1452.9032 | E17: =$B$4*E16/12 -> 1434.4153 | F17: =$B$4*F16/12 -> 1404.5493 | G17: =$B$4*G16/12 -> 1358.961 | H17: =$B$4*H16/12 -> 1323.2856 | I17: =$B$4*I16/12 -> 1297.2053 | ... X17: =$B$4*X16/12 -> 1358.2941

Sheet EV Data
A1: img href | B1: img src | C1: model | D1: current | E1: title-wrap | F1: battery | G1: price-range | H1: roofrack | I1: 3-phase | J1: plug-type2-ccs | K1: shape-sedan | L1: icons-row-1 | M1: heatpump | N1: tow-hitch | O1: towweight | P1: safety | Q1: icons-row-2 | R1: icons-row-2 2 | S1: icons-row-2 3 | T1: icons-row-2 4 | U1: tag | V1: acceleration | W1: tag 2 | X1: topspeed | Y1: tag 3 | Z1: erange_real | AA1: tag 4 | AB1: efficiency | AC1: tag 5 | AD1: fastcharge_speed_print | AE1: fastcharge_speed | AF1: country_de | AG1: country_nl | AH1: country_uk | AI1: pricefilter | AJ1: pricesort | AK1: date_from | AL1: rank | AM1: id | AN1: v2xl | AO1: icons-row-2 5 | AP1: size-c | AQ1: shape-hatchback | AR1: size-b | AT1: Efficiency | AU1: km/kWh | AV1: price-range | AW1: Top Speed | AX1: battery | AY1: Range | AZ1: Acceleration | BB1: https://ev-database.org/compare/efficiency-electric-vehicle-most-efficient#sort:path~type~order=.efficiency~number~asc|rs-price:prev~next=10000~100000|rs-range:prev~next=0~1000|rs-fastcharge:prev~next=0~1500|rs-acceleration:prev~next=2~23|rs-topspeed:prev~next=110~350|rs-battery:prev~next=10~200|rs-towweight:prev~next=0~2500|rs-eff:prev~next=100~350|rs-safety:prev~next=-1~5|paging:currentPage=8|paging:number=50
A2: https://ev-database.org/car/1991/Tesla-Model-3 | B2: https://ev-database.org/img/auto/Tesla_Model_3_2024/Tesla_Model_3_2024-01-thumb.jpg | C2: Model 3 | D2: Available to order since September 2023 | E2: kWh useable battery *| /km of range | F2: 57.5 | G2: 102 | H2: Roofbox possible | I2: 3-Phase Charging | J2: Type 2 CCS | K2: Sedan | L2: 5 | M2: Heatpump | N2: Towbar possible | O2: 1000 | P2: -1 | Q2: V2 | R2: L | S2: H | T2: G | U2: 0 - 100 | V2: 6.1 sec | W2: Top Speed | X2: 201 km/h | Y2: Range | Z2: 420 km | AA2: Efficiency | AB2: 137 Wh/km | AC2: Fastcharge | AD2: 730 km/h | AE2: 730 | AF2: 40.97 | AG2: 40.99 | AH2: £39,990 | AI2: 42649 | AJ2: 42649 | AK2: 1.69E+09 | AL2: 7170 | AM2: 1991 | AT2: 137 | AU2: 7.30 | AV2: 102 | AW2: 201 | AX2: 57.5 | AY2: 420 | AZ2: 45297
A3: https://ev-database.org/car/3034/Tesla-Model-3-Long-Range-RWD | B3: https://ev-database.org/img/auto/Tesla_Model_3_2024/Tesla_Model_3_2024-01-thumb.jpg | C3: Model 3 Long Range RWD | D3: Available to order since October 2024 | E3: kWh useable battery *| /km of range* | F3: 75 | G3: 87 | H3: Roofbox possible | I3: 3-Phase Charging | J3: Type 2 CCS | K3: Sedan | L3: 5 | M3: Heatpump | N3: Towbar possible | O3: 1000 | P3: -1 | Q3: V2 | R3: L | S3: H | T3: G | U3: 0 - 100 | V3: 5.2 sec | W3: Top Speed | X3: 201 km/h | Y3: Range* | Z3: 545 km | AA3: Efficiency* | AB3: 138 Wh/km | AC3: Fastcharge | AD3: 840 km/h | AE3: 840 | AF3: 44.99 | AG3: 45.99 | AH3: £44,990 | AI3: 47572 | AJ3: 47572 | AK3: 1.73E+09 | AL3: 3612 | AM3: 3034 | AT3: 138 | AU3: 7.25 | AV3: 87 | AW3: 201 | AX3: 75 | AY3: 545 | AZ3: 45327
A4: https://ev-database.org/car/1992/Tesla-Model-3-Long-Range-Dual-Motor | B4: https://ev-database.org/img/auto/Tesla_Model_3_2024/Tesla_Model_3_2024-01-thumb.jpg | C4: Model 3 Long Range Dual Motor | D4: Available to order since September 2023 | E4: kWh useable battery *| /km of range | F4: 75 | G4: 101 | H4: Roofbox possible | I4: 3-Phase Charging | J4: Type 2 CCS | K4: Sedan | L4: 5 | M4: Heatpump | N4: Towbar possible | O4: 1000 | P4: -1 | Q4: V2 | R4: L | S4: H | T4: G | U4: 0 - 100 | V4: 4.4 sec | W4: Top Speed | X4: 201 km/h | Y4: Range | Z4: 525 km | AA4: Efficiency | AB4: 143 Wh/km | AC4: Fastcharge | AD4: 810 km/h | AE4: 810 | AF4: 49.99 | AG4: 50.99 | AH4: £49,990 | AI4: 52822 | AJ4: 52822 | AK4: 1.69E+09 | AL4: 3902 | AM4: 1992 | AT4: 143 | AU4: 6.99 | AV4: 101 | AW4: 201 | AX4: 75 | AY4: 525 | AZ4: 45386
A5: https://ev-database.org/car/1717/Hyundai-IONIQ-6-Standard-Range-2WD | B5: https://ev-database.org/img/auto/Hyundai_IONIQ6_2022/Hyundai_IONIQ6_2022-01-thumb.jpg | C5: IONIQ 6 Standard Range 2WD | D5: Available to order since January 2023 | E5: kWh useable battery *| /km of range* | F5: 50 | G5: 134 | H5: Roofbox possible | I5: 3-Phase Charging | J5: Type 2 CCS | K5: Sedan | L5: 5 | M5: Heatpump | N5: Towbar possible | O5: 750 | P5: 5 | Q5: 5 | R5: V2 | S5: L | T5: H | U5: 0 - 100 | V5: 8.8 sec | W5: Top Speed | X5: 185 km/h | Y5: Range* | Z5: 335 km | AA5: Efficiency* | AB5: 149 Wh/km | AC5: Fastcharge | AD5: 780 km/h | AE5: 780 | AF5: 43.9 | AG5: 45.895 | AH5: N/A | AI5: 44897 | AJ5: 44897 | AK5: 1.67E+09 | AL5: 795 | AM5: 1717 | AN5: V2XL | AO5: G | AT5: 149 | AU5: 6.71 | AV5: 134 | AW5: 185 | AX5: 50 | AY5: 335 | AZ5: 45512
A6: https://ev-database.org/car/1718/Hyundai-IONIQ-6-Long-Range-2WD | B6: https://ev-database.org/img/auto/Hyundai_IONIQ6_2022/Hyundai_IONIQ6_2022-01-thumb.jpg | C6: IONIQ 6 Long Range 2WD | D6: Available to order since December 2022 | E6: kWh useable battery *| /km of range | F6: 74 | G6: 107 | H6: Roofbox possible | I6: 3-Phase Charging | J6: Type 2 CCS | K6: Sedan | L6: 5 | M6: Heatpump | N6: Towbar possible | O6: 1500 | P6: 5 | Q6: 5 | R6: V2 | S6: L | T6: H | U6: 0 - 100 | V6: 7.4 sec | W6: Top Speed | X6: 185 km/h | Y6: Range | Z6: 495 km | AA6: Efficiency | AB6: 149 Wh/km | AC6: Fastcharge | AD6: 1290 km/h | AE6: 1290 | AF6: 54 | AG6: 50.895 | AH6: £47,040 | AI6: 52997 | AJ6: 52997 | AK6: 1.67E+09 | AL6: 1006 | AM6: 1718 | AN6: V2XL | AO6: G | AT6: 149 | AU6: 6.71 | AV6: 107 | AW6: 185 | AX6: 74 | AY6: 495 | AZ6: 45389
A7: https://ev-database.org/car/3050/Citroen-e-C4-X-54-kWh | B7: https://ev-database.org/img/auto/Citroen_e-C4_X_2024/Citroen_e-C4_X_2024-01-thumb.jpg | C7: e-C4 X 54 kWh | D7: Available to order since October 2024 | E7: kWh useable battery | /km of range* | F7: 50.8 | G7: 107 | H7: Roofbox possible | I7: 3-Phase Charging | J7: Type 2 CCS | K7: Sedan | L7: 5 | M7: Heatpump | P7: 4 | Q7: 4 | R7: V2 | S7: L | T7: H | U7: 0 - 100 | V7: 10.1 sec | W7: Top Speed | X7: 150 km/h | Y7: Range* | Z7: 340 km | AA7: Efficiency* | AB7: 149 Wh/km | AC7: Fastcharge | AD7: 490 km/h | AE7: 490 | AF7: 34.8 | AG7: 38.165 | AH7: N/A | AI7: 36482 | AJ7: 36482 | AK7: 1.73E+09 | AL7: 594 | AM7: 3050 | AN7: V2XL | AO7: G | AP7: C | AT7: 149 | AU7: 6.71 | AV7: 107 | AW7: 150 | AX7: 50.8 | AY7: 340 | AZ7: 45301
A8: https://ev-database.org/car/2126/Dacia-Spring-Electric-45 | B8: https://ev-database.org/img/auto/Dacia_Spring_Electric_2024/Dacia_Spring_Electric_2024-01-thumb.jpg | C8: Spring Electric 45 | D8: Available to order since April 2024 | E8: kWh useable battery *| /km of range* | F8: 25 | G8: 107 | J8: Type 2 CCS | L8: 4 | P8: -1 | Q8: V2 | R8: L | S8: H | T8: G | U8: 0 - 100* | V8: 19.1 sec | W8: Top Speed | X8: 125 km/h | Y8: Range* | Z8: 165 km | AA8: Efficiency* | AB8: 152 Wh/km | AC8: Fastcharge | AD8: 180 km/h | AE8: 180 | AF8: 16.9 | AG8: 18.95 | AH8: £14,995 | AI8: 17698 | AJ8: 17698 | AK8: 1.71E+09 | AL8: 758 | AM8: 2126 | AQ8: Hatchback | AT8: 152 | AU8: 6.58 | AV8: 107 | AW8: 125 | AX8: 25 | AY8: 165 | AZ8: 45310
A9: https://ev-database.org/car/3048/Citroen-e-C4-54-kWh | B9: https://ev-database.org/img/auto/Citroen_e-C4_2024/Citroen_e-C4_2024-01-thumb.jpg | C9: e-C4 54 kWh | D9: Available to order since October 2024 | E9: kWh useable battery | /km of range* | F9: 50.8 | G9: 107 | H9: Roofbox possible | I9: 3-Phase Charging | J9: Type 2 CCS | L9: 5 | M9: Heatpump | P9: 4 | Q9: 4 | R9: V2 | S9: L | T9: H | U9: 0 - 100 | V9: 10.0 sec | W9: Top Speed | X9: 150 km/h | Y9: Range* | Z9: 335 km | AA9: Efficiency* | AB9: 152 Wh/km | AC9: Fastcharge | AD9: 480 km/h | AE9: 480 | AF9: 34.1 | AG9: 37.465 | AH9: N/A | AI9: 35782 | AJ9: 35782 | AK9: 1.73E+09 | AL9: 280 | AM9: 3048 | AN9: V2XL | AO9: G | AP9: C | AQ9: Hatchback | AT9: 152 | AU9: 6.58 | AV9: 107 | AW9: 150 | AX9: 50.8 | AY9: 335 | AZ9: 10
A10: https://ev-database.org/car/1942/Opel-Corsa-Electric-51-kWh | B10: https://ev-database.org/img/auto/Opel_Corsa_Electric_2023/Opel_Corsa_Electric_2023-01-thumb.jpg | C10: Corsa Electric 51 kWh | D10: Available to order since July 2023 | E10: kWh useable battery | /km of range* | F10: 48.1 | G10: 124 | H10: Roofbox possible | I10: 3-Phase Charging | J10: Type 2 CCS | L10: 5 | M10: Heatpump | P10: -1 | Q10: V2 | R10: L | S10: H | T10: G | U10: 0 - 100 | V10: 8.1 sec | W10: Top Speed | X10: 150 km/h | Y10: Range* | Z10: 315 km | AA10: Efficiency* | AB10: 153 Wh/km | AC10: Fastcharge | AD10: 490 km/h | AE10: 490 | AF10: 38.045 | AG10: 37.999 | AH10: £35,475 | AI10: 38946 | AJ10: 38946 | AK10: 1.69E+09 | AL10: 452 | AM10: 1942 | AQ10: Hatchback | AR10: B | AT10: 153 | AU10: 6.54 | AV10: 124 | AW10: 150 | AX10: 48.1 | AY10: 315 | AZ10: 45299
A11: https://ev-database.org/car/2188/Tesla-Model-3-Performance | B11: https://ev-database.org/img/auto/Tesla_Model_3_Performance_2024/Tesla_Model_3_Performance_2024-01-thumb.jpg | C11: Model 3 Performance | D11: Available to order since April 2024 | E11: kWh useable battery *| /km of range | F11: 75 | G11: 126 | H11: Roofbox possible | I11: 3-Phase Charging | J11: Type 2 CCS | K11: Sedan | L11: 5 | M11: Heatpump | P11: -1 | Q11: V2 | R11: L | S11: H | T11: G | U11: 0 - 100* | V11: 3.2 sec | W11: Top Speed | X11: 262 km/h | Y11: Range | Z11: 490 km | AA11: Efficiency | AB11: 153 Wh/km | AC11: Fastcharge* | AD11: 760 km/h | AE11: 760 | AF11: 58.47 | AG11: 58.49 | AH11: £59,990 | AI11: 61982 | AJ11: 61982 | AK11: 1.71E+09 | AL11: 1603 | AM11: 2188 | AT11: 153 | AU11: 6.54 | AV11: 126 | AW11: 262 | AX11: 75 | AY11: 490 | AZ11: 45325
A12: https://ev-database.org/car/3035/Dongfeng-Box-314-kWh | B12: https://ev-database.org/img/auto/Dongfeng_Box/Dongfeng_Box-01-thumb.jpg | C12: Box 31.4 kWh | E12: kWh useable battery *| /km of range* | F12: 29 | G12: 118 | J12: Type 2 CCS | L12: 5 | P12: -1 | Q12: V2 | R12: L | S12: H | T12: G | U12: 0 - 100* | V12: 12.5 sec | W12: Top Speed | X12: 140 km/h | Y12: Range* | Z12: 190 km | AA12: Efficiency* | AB12: 153 Wh/km | AC12: Fastcharge | AD12: 180 km/h | AE12: 180 | AF12: N/A | AG12: 22.4 | AH12: N/A | AI12: 22400 | AJ12: 22400 | AK12: 1.75E+09 | AL12: 351 | AM12: 3035 | AN12: V2XL | AQ12: Hatchback | AR12: B | AT12: 153 | AU12: 6.54 | AV12: 118 | AW12: 140 | AX12: 29 | AY12: 190 | AZ12: 45424
A13: https://ev-database.org/car/1536/Renault-Megane-E-Tech-EV40-130hp | B13: https://ev-database.org/img/auto/Renault_Megane_ETech/Renault_Megane_ETech-01-thumb.jpg | C13: Megane E-Tech EV40 130hp | D13: Available to order since April 2022 | E13: kWh useable battery | /km of range* | F13: 40 | G13: 151 | H13: Roofbox possible | I13: 3-Phase Charging | J13: Type 2 CCS | L13: 5 | M13: Heatpump | N13: Towbar possible | O13: 500 | P13: 5 | Q13: 5 | R13: V2 | S13: L | T13: H | U13: 0 - 100 | V13: 10.0 sec | W13: Top Speed | X13: 150 km/h | Y13: Range* | Z13: 260 km | AA13: Efficiency* | AB13: 154 Wh/km | AC13: Fastcharge | AD13: 340 km/h | AE13: 340 | AF13: 42 | AG13: 36.37 | AH13: N/A | AI13: 39185 | AJ13: 39185 | AK13: 1.65E+09 | AL13: 237 | AM13: 1536 | AO13: G | AP13: C | AQ13: Hatchback | AT13: 154 | AU13: 6.49 | AV13: 151 | AW13: 150 | AX13: 40 | AY13: 260 | AZ13: 10
A14: https://ev-database.org/car/1938/Citroen-e-C4-54-kWh | B14: https://ev-database.org/img/auto/Citroen_e-C4/Citroen_e-C4-01-thumb.jpg | C14: e-C4 54 kWh | D14: Available to order since June 2023 | E14: kWh useable battery | /km of range* | F14: 50.8 | G14: 125 | H14: Roofbox possible | I14: 3-Phase Charging | J14: Type 2 CCS | L14: 5 | M14: Heatpump | P14: 4 | Q14: 4 | R14: V2 | S14: L | T14: H | U14: 0 - 100 | V14: 9.2 sec | W14: Top Speed* | X14: 150 km/h | Y14: Range* | Z14: 330 km | AA14: Efficiency* | AB14: 154 Wh/km | AC14: Fastcharge | AD14: 470 km/h | AE14: 470 | AF14: N/A | AG14: N/A | AH14: £35,800 | AI14: 41170 | AJ14: 41170 | AK14: 1.69E+09 | AL14: 166 | AM14: 1938 | AO14: G | AP14: C | AQ14: Hatchback | AT14: 154 | AU14: 6.49 | AV14: 125 | AW14: 150 | AX14: 50.8 | AY14: 330 | AZ14: 45331
A15: https://ev-database.org/car/1939/Citroen-e-C4-X-54-kWh | B15: https://ev-database.org/img/auto/Citroen_e-C4_X/Citroen_e-C4_X-01-thumb.jpg | C15: e-C4 X 54 kWh | D15: Available to order since February 2023 | E15: kWh useable battery | /km of range | F15: 50.8 | G15: 125 | H15: Roofbox possible | I15: 3-Phase Charging | J15: Type 2 CCS | K15: Sedan | L15: 5 | M15: Heatpump | P15: 4 | Q15: 4 | R15: V2 | S15: L | T15: H | U15: 0 - 100 | V15: 9.3 sec | W15: Top Speed* | X15: 150 km/h | Y15: Range | Z15: 330 km | AA15: Efficiency | AB15: 154 Wh/km | AC15: Fastcharge | AD15: 470 km/h | AE15: 470 | AF15: N/A | AG15: N/A | AH15: £35,800 | AI15: 41170 | AJ15: 41170 | AK15: 1.68E+09 | AL15: 192 | AM15: 1939 | AO15: G | AP15: C | AT15: 154 | AU15: 6.49 | AV15: 125 | AW15: 150 | AX15: 50.8 | AY15: 330 | AZ15: 45360
A16: https://ev-database.org/car/1949/Peugeot-e-208-51-kWh | B16: https://ev-database.org/img/auto/Peugeot_e-208_2024/Peugeot_e-208_2024-01-thumb.jpg | C16: e-208 51 kWh | D16: Available to order since August 2023 | E16: kWh useable battery | /km of range* | F16: 48.1 | G16: 126 | I16: 3-Phase Charging | J16: Type 2 CCS | L16: 5 | M16: Heatpump | P16: -1 | Q16: V2 | R16: L | S16: H | T16: G | U16: 0 - 100 | V16: 8.2 sec | W16: Top Speed | X16: 150 km/h | Y16: Range* | Z16: 310 km | AA16: Efficiency* | AB16: 155 Wh/km | AC16: Fastcharge | AD16: 480 km/h | AE16: 480 | AF16: 40.875 | AG16: 39.17 | AH16: £32,400 | AI16: 39101 | AJ16: 39101 | AK16: 1.69E+09 | AL16: 397 | AM16: 1949 | AQ16: Hatchback | AR16: B | AT16: 155 | AU16: 6.45 | AV16: 126 | AW16: 150 | AX16: 48.1 | AY16: 310 | AZ16: 45330
A17: https://ev-database.org/car/2117/Lancia-Ypsilon | B17: https://ev-database.org/img/auto/Lancia_Ypsilon/Lancia_Ypsilon-01-thumb.jpg | C17: Ypsilon | D17: Available to order since June 2024 | E17: kWh useable battery | /km of range* | F17: 48.1 | G17: 122 | I17: 3-Phase Charging | J17: Type 2 CCS | L17: 5 | M17: Heatpump | P17: -1 | Q17: V2 | R17: L | S17: H | T17: G | U17: 0 - 100 | V17: 8.2 sec | W17: Top Speed | X17: 150 km/h | Y17: Range* | Z17: 310 km | AA17: Efficiency* | AB17: 155 Wh/km | AC17: Fastcharge | AD17: 480 km/h | AE17: 480 | AF17: * €40,000 | AG17: 35.4 | AH17: N/A | AI17: 37700 | AJ17: 37700 | AK17: 1.72E+09 | AL17: 439 | AM17: 2117 | AQ17: Hatchback | AR17: B | AT17: 155 | AU17: 6.45 | AV17: 122 | AW17: 150 | AX17: 48.1 | AY17: 310 | AZ17: 45330
A18: https://ev-database.org/car/3039/Leapmotor-T03 | B18: https://ev-database.org/img/auto/Leapmotor_T03/Leapmotor_T03-01-thumb.jpg | C18: T03 | D18: Available to order since October 2024 | E18: kWh useable battery | /km of range* | F18: 37.3 | G18: 80 | J18: Type 2 CCS | L18: 4 | P18: -1 | Q18: V2 | R18: L | S18: H | T18: G | U18: 0 - 100 | V18: 12.7 sec | W18: Top Speed | X18: 130 km/h | Y18: Range* | Z18: 240 km | AA18: Efficiency* | AB18: 155 Wh/km | AC18: Fastcharge | AD18: 180 km/h | AE18: 180 | AF18: 18.9 | AG18: 19.95 | AH18: £15,995 | AI18: 19081 | AJ18: 19081 | AK18: 1.73E+09 | AL18: 846 | AM18: 3039 | AQ18: Hatchback | AT18: 155 | AU18: 6.45 | AV18: 80 | AW18: 130 | AX18: 37.3 | AY18: 240 | AZ18: 45485
A19: https://ev-database.org/car/3066/Peugeot-e-408-58-kWh | B19: https://ev-database.org/img/auto/Peugeot_e-408_2024/Peugeot_e-408_2024-01-thumb.jpg | C19: e-408 58 kWh | D19: Available to order since October 2024 | E19: kWh useable battery | /km of range* | F19: 58.2 | G19: 119 | I19: 3-Phase Charging | J19: Type 2 CCS | L19: 5 | M19: Heatpump | P19: -1 | Q19: V2 | R19: L | S19: H | T19: G | U19: 0 - 100 | V19: 7.2 sec | W19: Top Speed | X19: 160 km/h | Y19: Range* | Z19: 375 km | AA19: Efficiency* | AB19: 155 Wh/km | AC19: Fastcharge | AD19: 420 km/h | AE19: 420 | AF19: 44.6 | AG19: 44.78 | AH19: N/A | AI19: 44690 | AJ19: 44690 | AK19: 1.73E+09 | AL19: 867 | AM19: 3066 | AT19: 155 | AU19: 6.45 | AV19: 119 | AW19: 160 | AX19: 58.2 | AY19: 375 | AZ19: 45329
A20: https://ev-database.org/car/2127/Dacia-Spring-Electric-65 | B20: https://ev-database.org/img/auto/Dacia_Spring_Electric_2024/Dacia_Spring_Electric_2024-01-thumb.jpg | C20: Spring Electric 65 | D20: Available to order since April 2024 | E20: kWh useable battery *| /km of range* | F20: 25 | G20: 119 | J20: Type 2 CCS | L20: 4 | P20: -1 | Q20: V2 | R20: L | S20: H | T20: G | U20: 0 - 100* | V20: 13.7 sec | W20: Top Speed | X20: 125 km/h | Y20: Range* | Z20: 160 km | AA20: Efficiency* | AB20: 156 Wh/km | AC20: Fastcharge | AD20: 170 km/h | AE20: 170 | AF20: 18.9 | AG20: 19.95 | AH20: £15,995 | AI20: 19081 | AJ20: 19081 | AK20: 1.71E+09 | AL20: 506 | AM20: 2127 | AN20: V2XL | AQ20: Hatchback | AT20: 156 | AU20: 6.41 | AV20: 119 | AW20: 125 | AX20: 25 | AY20: 160 | AZ20: 45486
A21: https://ev-database.org/car/2198/BMW-i4-eDrive35 | B21: https://ev-database.org/img/auto/BMW_i4_2024/BMW_i4_2024-01-thumb.jpg | C21: i4 eDrive35 | D21: Available to order since June 2024 | E21: kWh useable battery | /km of range* | F21: 67.1 | G21: 137 | H21: Roofbox possible | I21: 3-Phase Charging | J21: Type 2 CCS | K21: Liftback | L21: 5 | M21: Heatpump | N21: Towbar possible | O21: 1600 | P21: -1 | Q21: V2 | R21: L | S21: H | T21: G | U21: 0 - 100 | V21: 6.0 sec | W21: Top Speed | X21: 190 km/h | Y21: Range* | Z21: 430 km | AA21: Efficiency* | AB21: 156 Wh/km | AC21: Fastcharge | AD21: 580 km/h | AE21: 580 | AF21: 57.5 | AG21: 59.728 | AH21: £51,270 | AI21: 58729 | AJ21: 58729 | AK21: 1.72E+09 | AL21: 532 | AM21: 2198 | AT21: 156 | AU21: 6.41 | AV21: 137 | AW21: 190 | AX21: 67.1 | AY21: 430 | AZ21: 6
A22: https://ev-database.org/car/2230/Hyundai-INSTER-Standard-Range | B22: https://ev-database.org/img/auto/Hyundai_Inster_2025/Hyundai_Inster_2025-01-thumb.jpg | C22: INSTER Standard Range | D22: Available to order since October 2024 | E22: kWh useable battery *| /km of range* | F22: 39 | G22: 100 | H22: Roofbox possible | I22: 3-Phase Charging | J22: Type 2 CCS | L22: 4 | M22: Heatpump | P22: -1 | Q22: V2 | R22: L | S22: H | T22: G | U22: 0 - 100 | V22: 11.7 sec | W22: Top Speed | X22: 140 km/h | Y22: Range* | Z22: 250 km | AA22: Efficiency* | AB22: 156 Wh/km | AC22: Fastcharge | AD22: 360 km/h | AE22: 360 | AF22: * €24,000 | AG22: 24.295 | AH22: £23,495 | AI22: 25104 | AJ22: 25104 | AK22: 1.73E+09 | AL22: 800 | AM22: 2230 | AN22: V2XL | AT22: 156 | AU22: 6.41 | AV22: 100 | AW22: 140 | AX22: 39 | AY22: 250 | AZ22: 45484
A23: https://ev-database.org/car/2231/Hyundai-INSTER-Long-Range | B23: https://ev-database.org/img/auto/Hyundai_Inster_2025/Hyundai_Inster_2025-01-thumb.jpg | C23: INSTER Long Range | D23: Available to order since October 2024 | E23: kWh useable battery *| /km of range* | F23: 46 | G23: 92 | H23: Roofbox possible | I23: 3-Phase Charging | J23: Type 2 CCS | L23: 4 | M23: Heatpump | P23: -1 | Q23: V2 | R23: L | S23: H | T23: G | U23: 0 - 100 | V23: 10.6 sec | W23: Top Speed | X23: 150 km/h | Y23: Range* | Z23: 295 km | AA23: Efficiency* | AB23: 156 Wh/km | AC23: Fastcharge | AD23: 420 km/h | AE23: 420 | AF23: * €27,000 | AG23: 25.995 | AH23: £25,045 | AI23: 27265 | AJ23: 27265 | AK23: 1.73E+09 | AL23: 1057 | AM23: 2231 | AN23: V2XL | AT23: 156 | AU23: 6.41 | AV23: 92 | AW23: 150 | AX23: 46 | AY23: 295 | AZ23: 45453
A24: https://ev-database.org/car/3053/Audi-A6-Sportback-e-tron | B24: https://ev-database.org/img/auto/Audi_A6_Sportback_etron_2024/Audi_A6_Sportback_etron_2024-01-thumb.jpg | C24: A6 Sportback e-tron | D24: Available to order since October 2024 | E24: kWh useable battery | /km of range* | F24: 75.8 | G24: 131 | H24: Roofbox possible | I24: 3-Phase Charging | J24: Type 2 CCS | K24: Liftback | L24: 5 | M24: Heatpump | N24: Towbar possible | O24: 2100 | P24: -1 | Q24: V2 | R24: L | S24: H | T24: G | U24: 0 - 100 | V24: 6.0 sec | W24: Top Speed | X24: 210 km/h | Y24: Range* | Z24: 485 km | AA24: Efficiency* | AB24: 156 Wh/km | AC24: Fastcharge | AD24: 920 km/h | AE24: 920 | AF24: 62.8 | AG24: 63.99 | AH24: N/A | AI24: 63395 | AJ24: 63395 | AK24: 1.73E+09 | AL24: 357 | AM24: 3053 | AT24: 156 | AU24: 6.41 | AV24: 131 | AW24: 210 | AX24: 75.8 | AY24: 485 | AZ24: 6
A25: https://ev-database.org/car/1941/Opel-Corsa-Electric-50-kWh | B25: https://ev-database.org/img/auto/Opel_Corsa_Electric_2023/Opel_Corsa_Electric_2023-01-thumb.jpg | C25: Corsa Electric 50 kWh | D25: Available to order since July 2023 | E25: kWh useable battery | /km of range* | F25: 46.3 | G25: 121 | H25: Roofbox possible | I25: 3-Phase Charging | J25: Type 2 CCS | L25: 5 | M25: Heatpump | P25: -1 | Q25: V2 | R25: L | S25: H | T25: G | U25: 0 - 100 | V25: 8.7 sec | W25: Top Speed | X25: 150 km/h | Y25: Range* | Z25: 295 km | AA25: Efficiency* | AB25: 157 Wh/km | AC25: Fastcharge | AD25: 470 km/h | AE25: 470 | AF25: 34.65 | AG25: 34.999 | AH25: £32,445 | AI25: 35653 | AJ25: 35653 | AK25: 1.69E+09 | AL25: 374 | AM25: 1941 | AQ25: Hatchback | AR25: B | AT25: 157 | AU25: 6.37 | AV25: 121 | AW25: 150 | AX25: 46.3 | AY25: 295 | AZ25: 45481
A26: https://ev-database.org/car/2133/Renault-5-E-Tech-40kWh-95hp | B26: https://ev-database.org/img/auto/Renault_5_ETech/Renault_5_ETech-01-thumb.jpg | C26: 5 E-Tech 40kWh 95hp | E26: kWh useable battery | /km of range* | F26: 40 | G26: 98 | I26: 3-Phase Charging | L26: 5 | M26: Heatpump | N26: Towbar possible | O26: 500 | P26: -1 | Q26: V2 | R26: L | S26: H | T26: G | U26: 0 - 100* | V26: 10.0 sec | W26: Top Speed | X26: 140 km/h | Y26: Range* | Z26: 255 km | AA26: Efficiency* | AB26: 157 Wh/km | AC26: Fastcharge | AD26: - | AF26: 24.9 | AG26: * €25,000 | AH26: * £22,000 | AI26: 25066 | AJ26: 25066 | AK26: 1.75E+09 | AL26: 493 | AM26: 2133 | AQ26: Hatchback | AR26: B | AT26: 157 | AU26: 6.37 | AV26: 98 | AW26: 140 | AX26: 40 | AY26: 255 | AZ26: 10
A27: https://ev-database.org/car/2134/Renault-5-E-Tech-40kWh-120hp | B27: https://ev-database.org/img/auto/Renault_5_ETech/Renault_5_ETech-01-thumb.jpg | C27: 5 E-Tech 40kWh 120hp | D27: Available to order since November 2024 | E27: kWh useable battery | /km of range* | F27: 40 | G27: 108 | I27: 3-Phase Charging | J27: Type 2 CCS | L27: 5 | M27: Heatpump | N27: Towbar possible | O27: 500 | P27: -1 | Q27: V2 | R27: L | S27: H | T27: G | U27: 0 - 100 | V27: 9.0 sec | W27: Top Speed | X27: 140 km/h | Y27: Range* | Z27: 255 km | AA27: Efficiency* | AB27: 157 Wh/km | AC27: Fastcharge | AD27: 330 km/h | AE27: 330 | AF27: 27.9 | AG27: 27.99 | AH27: £22,995 | AI27: 27444 | AJ27: 27444 | AK27: 1.73E+09 | AL27: 298 | AM27: 2134 | AN27: V2XL | AQ27: Hatchback | AR27: B | AT27: 157 | AU27: 6.37 | AV27: 108 | AW27: 140 | AX27: 40 | AY27: 255 | AZ27: 9
A28: https://ev-database.org/car/3036/Dongfeng-Box-423-kWh | B28: https://ev-database.org/img/auto/Dongfeng_Box/Dongfeng_Box-01-thumb.jpg | C28: Box 42.3 kWh | D28: Available to order since October 2024 | E28: kWh useable battery *| /km of range* | F28: 40 | G28: 92 | J28: Type 2 CCS | L28: 5 | P28: -1 | Q28: V2 | R28: L | S28: H | T28: G | U28: 0 - 100* | V28: 12.5 sec | W28: Top Speed | X28: 140 km/h | Y28: Range* | Z28: 255 km | AA28: Efficiency* | AB28: 157 Wh/km | AC28: Fastcharge | AD28: 240 km/h | AE28: 240 | AF28: N/A | AG28: 23.4 | AH28: N/A | AI28: 23400 | AJ28: 23400 | AK28: 1.73E+09 | AL28: 652 | AM28: 3036 | AN28: V2XL | AQ28: Hatchback | AR28: B | AT28: 157 | AU28: 6.37 | AV28: 92 | AW28: 140 | AX28: 40 | AY28: 255 | AZ28: 45424
A29: https://ev-database.org/car/3049/Citroen-e-C4-X | B29: https://ev-database.org/img/auto/Citroen_e-C4_X_2024/Citroen_e-C4_X_2024-01-thumb.jpg | C29: e-C4 X | D29: Available to order since October 2024 | E29: kWh useable battery | /km of range* | F29: 46.3 | G29: 116 | H29: Roofbox possible | I29: 3-Phase Charging | J29: Type 2 CCS | K29: Sedan | L29: 5 | M29: Heatpump | P29: 4 | Q29: 4 | R29: V2 | S29: L | T29: H | U29: 0 - 100 | V29: 10.8 sec | W29: Top Speed | X29: 150 km/h | Y29: Range* | Z29: 295 km | AA29: Efficiency* | AB29: 157 Wh/km | AC29: Fastcharge | AD29: 470 km/h | AE29: 470 | AF29: 32.6 | AG29: 35.915 | AH29: N/A | AI29: 34257 | AJ29: 34257 | AK29: 1.73E+09 | AL29: 192 | AM29: 3049 | AO29: G | AP29: C | AT29: 157 | AU29: 6.37 | AV29: 116 | AW29: 150 | AX29: 46.3 | AY29: 295 | AZ29: 45514
A30: https://ev-database.org/car/1327/Fiat-500e-Hatchback-24-kWh | B30: https://ev-database.org/img/auto/Fiat_500e_Hatchback_2020/Fiat_500e_Hatchback_2020-01-thumb.jpg | C30: 500e Hatchback 24 kWh | D30: Available to order since November 2020 | E30: kWh useable battery | /km of range* | F30: 45372 | G30: 219 | I30: 3-Phase Charging | J30: Type 2 CCS | L30: 4 | P30: 4 | Q30: 4 | R30: V2 | S30: L | T30: H | U30: 0 - 100 | V30: 9.0 sec | W30: Top Speed | X30: 135 km/h | Y30: Range* | Z30: 135 km | AA30: Efficiency* | AB30: 158 Wh/km | AC30: Fastcharge | AD30: 230 km/h | AE30: 230 | AF30: 30.99 | AG30: 28.99 | AH30: £24,995 | AI30: 29574 | AJ30: 29574 | AK30: 1.6E+09 | AL30: 297 | AM30: 1327 | AO30: G | AQ30: Hatchback | AR30: B | AT30: 158 | AU30: 6.33 | AV30: 219 | AW30: 135 | AX30: 45372 | AY30: 135 | AZ30: 9
A31: https://ev-database.org/car/1521/Renault-Megane-E-Tech-EV60-220hp | B31: https://ev-database.org/img/auto/Renault_Megane_ETech/Renault_Megane_ETech-01-thumb.jpg | C31: Megane E-Tech EV60 220hp | D31: Available to order since April 2022 | E31: kWh useable battery | /km of range | F31: 60 | G31: 113 | H31: Roofbox possible | I31: 3-Phase Charging | J31: Type 2 CCS | L31: 5 | M31: Heatpump | N31: Towbar possible | O31: 900 | P31: 5 | Q31: 5 | R31: V2 | S31: L | T31: H | U31: 0 - 100 | V31: 7.4 sec | W31: Top Speed | X31: 160 km/h | Y31: Range | Z31: 380 km | AA31: Efficiency | AB31: 158 Wh/km | AC31: Fastcharge | AD31: 530 km/h | AE31: 530 | AF31: 46.6 | AG31: 39.37 | AH31: £36,995 | AI31: 42838 | AJ31: 42838 | AK31: 1.65E+09 | AL31: 1414 | AM31: 1521 | AO31: G | AP31: C | AQ31: Hatchback | AT31: 158 | AU31: 6.33 | AV31: 113 | AW31: 160 | AX31: 60 | AY31: 380 | AZ31: 45389
A32: https://ev-database.org/car/1588/Renault-Megane-E-Tech-EV60-130hp | B32: https://ev-database.org/img/auto/Renault_Megane_ETech/Renault_Megane_ETech-01-thumb.jpg | C32: Megane E-Tech EV60 130hp | D32: Available to order since April 2022 | E32: kWh useable battery | /km of range* | F32: 60 | G32: 114 | H32: Roofbox possible | I32: 3-Phase Charging | J32: Type 2 CCS | L32: 5 | M32: Heatpump | N32: Towbar possible | O32: 500 | P32: 5 | Q32: 5 | R32: V2 | S32: L | T32: H | U32: 0 - 100 | V32: 10.5 sec | W32: Top Speed | X32: 150 km/h | Y32: Range* | Z32: 380 km | AA32: Efficiency* | AB32: 158 Wh/km | AC32: Fastcharge | AD32: 530 km/h | AE32: 530 | AF32: 47 | AG32: 39.37 | AH32: N/A | AI32: 43185 | AJ32: 43185 | AK32: 1.65E+09 | AL32: 237 | AM32: 1588 | AO32: G | AP32: C | AQ32: Hatchback | AT32: 158 | AU32: 6.33 | AV32: 114 | AW32: 150 | AX32: 60 | AY32: 380 | AZ32: 45422
A33: https://ev-database.org/car/1726/Fiat-500e-3plus1-24-kWh | B33: https://ev-database.org/img/auto/Fiat_500e_3plus1_2020/Fiat_500e_3plus1_2020-01-thumb.jpg | C33: 500e 3+1 24 kWh | D33: Available to order since July 2022 | E33: kWh useable battery | /km of range* | F33: 45372 | G33: 230 | I33: 3-Phase Charging | J33: Type 2 CCS | L33: 4 | P33: 4 | Q33: 4 | R33: V2 | S33: L | T33: H | U33: 0 - 100 | V33: 9.0 sec | W33: Top Speed | X33: 135 km/h | Y33: Range* | Z33: 135 km | AA33: Efficiency* | AB33: 158 Wh/km | AC33: Fastcharge | AD33: 230 km/h | AE33: 230 | AF33: N/A | AG33: 30.99 | AH33: N/A | AI33: 30990 | AJ33: 30990 | AK33: 1.66E+09 | AL33: 109 | AM33: 1726 | AO33: G | AQ33: Hatchback | AR33: B | AT33: 158 | AU33: 6.33 | AV33: 230 | AW33: 135 | AX33: 45372 | AY33: 135 | AZ33: 9
A34: https://ev-database.org/car/1727/Fiat-500e-Cabrio-24-kWh | B34: https://ev-database.org/img/auto/Fiat_500e_Convertible_2020/Fiat_500e_Convertible_2020-01-thumb.jpg | C34: 500e Cabrio 24 kWh | D34: Available to order since July 2022 | E34: kWh useable battery | /km of range* | F34: 45372 | G34: 250 | I34: 3-Phase Charging | J34: Type 2 CCS | L34: 4 | P34: 4 | Q34: 4 | R34: V2 | S34: L | T34: H | U34: 0 - 100 | V34: 9.0 sec | W34: Top Speed | X34: 135 km/h | Y34: Range* | Z34: 135 km | AA34: Efficiency* | AB34: 158 Wh/km | AC34: Fastcharge | AD34: 230 km/h | AE34: 230 | AF34: 35.49 | AG34: 31.99 | AH34: N/A | AI34: 33740 | AJ34: 33740 | AK34: 1.66E+09 | AL34: 114 | AM34: 1727 | AO34: G | AR34: B | AT34: 158 | AU34: 6.33 | AV34: 250 | AW34: 135 | AX34: 45372 | AY34: 135 | AZ34: 9
A35: https://ev-database.org/car/2199/BMW-i4-eDrive40 | B35: https://ev-database.org/img/auto/BMW_i4_2024/BMW_i4_2024-01-thumb.jpg | C35: i4 eDrive40 | D35: Available to order since June 2024 | E35: kWh useable battery | /km of range* | F35: 81.3 | G35: 124 | H35: Roofbox possible | I35: 3-Phase Charging | J35: Type 2 CCS | K35: Liftback | L35: 5 | M35: Heatpump | N35: Towbar possible | O35: 1600 | P35: -1 | Q35: V2 | R35: L | S35: H | T35: G | U35: 0 - 100 | V35: 5.6 sec | W35: Top Speed | X35: 190 km/h | Y35: Range* | Z35: 515 km | AA35: Efficiency* | AB35: 158 Wh/km | AC35: Fastcharge | AD35: 800 km/h | AE35: 800 | AF35: 60.5 | AG35: 63.358 | AH35: £59,365 | AI35: 64042 | AJ35: 64042 | AK35: 1.72E+09 | AL35: 1230 | AM35: 2199 | AT35: 158 | AU35: 6.33 | AV35: 124 | AW35: 190 | AX35: 81.3 | AY35: 515 | AZ35: 45448
A36: https://ev-database.org/car/2270/Audi-A6-Sportback-e-tron-performance | B36: https://ev-database.org/img/auto/Audi_A6_Sportback_etron_2024/Audi_A6_Sportback_etron_2024-01-thumb.jpg | C36: A6 Sportback e-tron performance | D36: Available to order since September 2024 | E36: kWh useable battery | /km of range* | F36: 94.9 | G36: 129 | H36: Roofbox possible | I36: 3-Phase Charging | J36: Type 2 CCS | K36: Liftback | L36: 5 | M36: Heatpump | N36: Towbar possible | O36: 2100 | P36: -1 | Q36: V2 | R36: L | S36: H | T36: G | U36: 0 - 100 | V36: 5.4 sec | W36: Top Speed | X36: 210 km/h | Y36: Range* | Z36: 600 km | AA36: Efficiency* | AB36: 158 Wh/km | AC36: Fastcharge | AD36: 1200 km/h | AE36: 1200 | AF36: 75.6 | AG36: 75.99 | AH36: £69,900 | AI36: 77325 | AJ36: 77325 | AK36: 1.73E+09 | AL36: 1056 | AM36: 2270 | AT36: 158 | AU36: 6.33 | AV36: 129 | AW36: 210 | AX36: 94.9 | AY36: 600 | AZ36: 45387
A37: https://ev-database.org/car/1285/Fiat-500e-Hatchback-42-kWh | B37: https://ev-database.org/img/auto/Fiat_500e_Hatchback_2020/Fiat_500e_Hatchback_2020-01-thumb.jpg | C37: 500e Hatchback 42 kWh | D37: Available to order since November 2020 | E37: kWh useable battery | /km of range | F37: 37.3 | G37: 144 | I37: 3-Phase Charging | J37: Type 2 CCS | L37: 4 | P37: 4 | Q37: 4 | R37: V2 | S37: L | T37: H | U37: 0 - 100 | V37: 9.0 sec | W37: Top Speed | X37: 150 km/h | Y37: Range | Z37: 235 km | AA37: Efficiency | AB37: 159 Wh/km | AC37: Fastcharge | AD37: 390 km/h | AE37: 390 | AF37: 34.99 | AG37: 34.49 | AH37: £27,995 | AI37: 33891 | AJ37: 33891 | AK37: 1.6E+09 | AL37: 1146 | AM37: 1285 | AO37: G | AQ37: Hatchback | AR37: B | AT37: 159 | AU37: 6.29 | AV37: 144 | AW37: 150 | AX37: 37.3 | AY37: 235 | AZ37: 9
A38: https://ev-database.org/car/1317/Lucid-Air-Touring | B38: https://ev-database.org/img/auto/Lucid_Air/Lucid_Air-01-thumb.jpg | C38: Air Touring | D38: Available to order since May 2023 | E38: kWh useable battery *| /km of range* | F38: 92 | G38: 173 | I38: 3-Phase Charging | J38: Type 2 CCS | K38: Sedan | L38: 5 | P38: 5 | Q38: 5 | R38: V2 | S38: L | T38: H | U38: 0 - 100 | V38: 3.2 sec | W38: Top Speed | X38: 250 km/h | Y38: Range* | Z38: 580 km | AA38: Efficiency* | AB38: 159 Wh/km | AC38: Fastcharge* | AD38: 970 km/h | AE38: 970 | AF38: 99 | AG38: 102 | AH38: N/A | AI38: 100000 | AJ38: 100500 | AK38: 1.68E+09 | AL38: 310 | AM38: 1317 | AN38: V2XL | AO38: G | AT38: 159 | AU38: 6.29 | AV38: 173 | AW38: 250 | AX38: 92 | AY38: 580 | AZ38: 45325
A39: https://ev-database.org/car/1328/Fiat-500e-3plus1-42-kWh | B39: https://ev-database.org/img/auto/Fiat_500e_3plus1_2020/Fiat_500e_3plus1_2020-01-thumb.jpg | C39: 500e 3+1 42 kWh | D39: Available to order since November 2020 | E39: kWh useable battery | /km of range* | F39: 37.3 | G39: 154 | I39: 3-Phase Charging | J39: Type 2 CCS | L39: 4 | P39: 4 | Q39: 4 | R39: V2 | S39: L | T39: H | U39: 0 - 100 | V39: 9.0 sec | W39: Top Speed | X39: 150 km/h | Y39: Range* | Z39: 235 km | AA39: Efficiency* | AB39: 159 Wh/km | AC39: Fastcharge | AD39: 390 km/h | AE39: 390 | AF39: 36.99 | AG39: 35.49 | AH39: N/A | AI39: 36240 | AJ39: 36240 | AK39: 1.6E+09 | AL39: 157 | AM39: 1328 | AO39: G | AQ39: Hatchback | AR39: B | AT39: 159 | AU39: 6.29 | AV39: 154 | AW39: 150 | AX39: 37.3 | AY39: 235 | AZ39: 9
A40: https://ev-database.org/car/1792/Opel-Astra-Electric | B40: https://ev-database.org/img/auto/Opel_Astra_Electric/Opel_Astra_Electric-01-thumb.jpg | C40: Astra Electric | D40: Available to order since June 2023 | E40: kWh useable battery | /km of range* | F40: 50.8 | G40: 131 | I40: 3-Phase Charging | J40: Type 2 CCS | L40: 5 | M40: Heatpump | N40: Towbar possible | O40: 0 | P40: -1 | Q40: V2 | R40: L | S40: H | T40: G | U40: 0 - 100 | V40: 9.2 sec | W40: Top Speed | X40: 170 km/h | Y40: Range* | Z40: 320 km | AA40: Efficiency* | AB40: 159 Wh/km | AC40: Fastcharge | AD40: 510 km/h | AE40: 510 | AF40: 41.99 | AG40: 39.999 | AH40: £37,795 | AI40: 41817 | AJ40: 41817 | AK40: 1.69E+09 | AL40: 608 | AM40: 1792 | AP40: C | AQ40: Hatchback | AT40: 159 | AU40: 6.29 | AV40: 131 | AW40: 170 | AX40: 50.8 | AY40: 320 | AZ40: 45331
...

Sheet Electricity emissions
A1: 1. Subregion Output Emission Rates (eGRID2022) | T1: 2. Subregion Resource Mix (eGRID2022)
A2: eGRID subregion acronym | B2: eGRID subregion name | C2: Total output emission rates | J2: Non-baseload output emission rates | Q2: Grid Gross Loss (%) | T2: eGRID subregion acronym | U2: eGRID subregion name | V2: Nameplate Capacity (MW) | W2: Net Generation (MWh) | X2: Generation Resource Mix (percent)*
C3: lb/MWh | J3: lb/MWh | X3: Coal | Y3: Oil | Z3: Gas | AA3: Other Fossil | AB3: Nuclear | AC3: Hydro | AD3: Biomass | AE3: Wind | AF3: Solar | AG3: Geo- thermal | AH3: Other unknown/ purchased fuel
C4: CO2 | D4: CH4 | E4: N2O | F4: CO2e | G4: Annual NOX | H4: Ozone Season NOX | I4: SO2 | J4: CO2 | K4: CH4 | L4: N2O | M4: CO2e | N4: Annual NOX | O4: Ozone Season NOX | P4: SO2 | T4: AKGD | U4: ASCC Alaska Grid | V4: 2.17 | W4: 5,016,815 | X4: 14.5% | Y4: 8.8% | Z4: 62.3% | AA4: 0.0% | AB4: 0.0% | AC4: 11.5% | AD4: 0.8% | AE4: 2.1% | AF4: 0.0% | AG4: 0.0% | AH4: 0.0%
A5: AKGD | B5: ASCC Alaska Grid | C5: 1,052.1 | D5: 88 | E5: 12 | F5: 1,057.8 | G5: 45296 | H5: 45387 | I5: 423 | J5: 1,224.5 | K5: 123 | L5: 17 | M5: 1,232.5 | N5: 7.0 | O5: 45450 | P5: 583 | Q5: 5.0% | T5: AKMS | U5: ASCC Miscellaneous | V5: 920 | W5: 1,677,313 | X5: 0.0% | Y5: 24.1% | Z5: 6.3% | AA5: 0.0% | AB5: 0.0% | AC5: 67.7% | AD5: 0.0% | AE5: 2.0% | AF5: 0.0% | AG5: 0.0% | AH5: 0.0%
A6: AKMS | B6: ASCC Miscellaneous | C6: 495.8 | D6: 23 | E6: 4 | F6: 497.6 | G6: 45542 | H6: 45358 | I6: 680 | J6: 1,587.9 | K6: 69 | L6: 12 | M6: 1,593.3 | N6: 45407 | O6: 45467 | P6: 2185 | Q6: 5.0% | T6: AZNM | U6: WECC Southwest | V6: 52.133 | W6: 170,369,549 | X6: 15.7% | Y6: 0.0% | Z6: 44.3% | AA6: 0.0% | AB6: 18.7% | AC6: 3.1% | AD6: 0.3% | AE6: 7.4% | AF6: 7.0% | AG6: 3.4% | AH6: 0.0%
A7: AZNM | B7: WECC Southwest | C7: 776.0 | D7: 51 | E7: 7 | F7: 779.4 | G7: 0.4 | H7: 0.4 | I7: 121 | J7: 1,205.2 | K7: 65 | L7: 9 | M7: 1,209.5 | N7: 0.7 | O7: 0.7 | P7: 162 | Q7: 5.1% | T7: CAMX | U7: WECC California | V7: 93.348 | W7: 209,353,986 | X7: 2.7% | Y7: 0.1% | Z7: 46.2% | AA7: 0.8% | AB7: 8.4% | AC7: 7.9% | AD7: 2.4% | AE7: 7.2% | AF7: 20.4% | AG7: 3.9% | AH7: 0.0%
A8: CAMX | B8: WECC California | C8: 497.4 | D8: 30 | E8: 4 | F8: 499.3 | G8: 0.5 | H8: 0.4 | I8: 30 | J8: 1,055.0 | K8: 49 | L8: 6 | M8: 1,058.0 | N8: 0.8 | O8: 0.7 | P8: 55 | Q8: 5.1% | T8: ERCT | U8: ERCOT All | V8: 139.101 | W8: 458,259,386 | X8: 15.5% | Y8: 0.1% | Z8: 46.8% | AA8: 0.4% | AB8: 9.1% | AC8: 0.1% | AD8: 0.2% | AE8: 23.0% | AF8: 4.7% | AG8: 0.0% | AH8: 0.1%
A9: ERCT | B9: ERCOT All | C9: 771.1 | D9: 49 | E9: 7 | F9: 774.3 | G9: 0.5 | H9: 0.5 | I9: 407 | J9: 1,194.9 | K9: 67 | L9: 9 | M9: 1,199.2 | N9: 0.9 | O9: 0.9 | P9: 665 | Q9: 5.1% | T9: FRCC | U9: FRCC All | V9: 70.81 | W9: 250,233,811 | X9: 6.1% | Y9: 0.5% | Z9: 74.4% | AA9: 0.6% | AB9: 12.3% | AC9: 0.1% | AD9: 1.4% | AE9: 0.0% | AF9: 4.3% | AG9: 0.0% | AH9: 0.3%
A10: FRCC | B10: FRCC All | C10: 813.8 | D10: 48 | E10: 6 | F10: 816.9 | G10: 0.3 | H10: 0.3 | I10: 142 | J10: 1,044.4 | K10: 56 | L10: 7 | M10: 1,048.0 | N10: 0.4 | O10: 0.4 | P10: 208 | Q10: 5.1% | T10: HIMS | U10: HICC Miscellaneous | V10: 1.045 | W10: 2,708,213 | X10: 0.0% | Y10: 64.4% | Z10: 0.0% | AA10: 0.0% | AB10: 0.0% | AC10: 4.1% | AD10: 3.6% | AE10: 12.6% | AF10: 5.5% | AG10: 7.7% | AH10: 2.1%
A11: HIMS | B11: HICC Miscellaneous | C11: 1,155.5 | D11: 124 | E11: 19 | F11: 1,163.1 | G11: 45329 | H11: 45358 | I11: 3069 | J11: 1,619.2 | K11: 157 | L11: 25 | M11: 1,629.6 | N11: 45393 | O11: 45546 | P11: 4074 | Q11: 5.4% | T11: HIOA | U11: HICC Oahu | V11: 2.298 | W11: 6,595,979 | X11: 9.8% | Y11: 74.5% | Z11: 0.0% | AA11: 3.1% | AB11: 0.0% | AC11: 0.0% | AD11: 2.7% | AE11: 3.8% | AF11: 6.1% | AG11: 0.0% | AH11: 0.0%
A12: HIOA | B12: HICC Oahu | C12: 1,575.4 | D12: 163 | E12: 25 | F12: 1,586.9 | G12: 45538 | H12: 45476 | I12: 6353 | J12: 1,810.3 | K12: 177 | L12: 28 | M12: 1,822.9 | N12: 45386 | O12: 45326 | P12: 7330 | Q12: 5.4% | T12: MROE | U12: MRO East | V12: 8.453 | W12: 22,864,489 | X12: 45.8% | Y12: 0.7% | Z12: 37.8% | AA12: 0.1% | AB12: 0.0% | AC12: 4.8% | AD12: 3.7% | AE12: 3.8% | AF12: 3.2% | AG12: 0.0% | AH12: 0.0%
A13: MROE | B13: MRO East | C13: 1,479.6 | D13: 133 | E13: 19 | F13: 1,488.7 | G13: 1.0 | H13: 1.0 | I13: 306 | J13: 1,672.9 | K13: 147 | L13: 21 | M13: 1,682.8 | N13: 45292 | O13: 45323 | P13: 334 | Q13: 5.1% | T13: MROW | U13: MRO West | V13: 76.84 | W13: 251,623,837 | X13: 38.0% | Y13: 0.1% | Z13: 8.3% | AA13: 0.1% | AB13: 8.1% | AC13: 3.9% | AD13: 0.7% | AE13: 39.8% | AF13: 1.0% | AG13: 0.0% | AH13: 0.1%
A14: MROW | B14: MRO West | C14: 936.5 | D14: 102 | E14: 15 | F14: 943.4 | G14: 0.8 | H14: 0.9 | I14: 907 | J14: 1,794.7 | K14: 183 | L14: 26 | M14: 1,807.0 | N14: 45444 | O14: 45444 | P14: 1640 | Q14: 5.1% | T14: NEWE | U14: NPCC New England | V14: 38.88 | W14: 105,455,877 | X14: 0.3% | Y14: 1.8% | Z14: 52.7% | AA14: 1.6% | AB14: 26.0% | AC14: 5.9% | AD14: 4.5% | AE14: 3.8% | AF14: 3.3% | AG14: 0.0% | AH14: 0.1%
A15: NEWE | B15: NPCC New England | C15: 536.4 | D15: 63 | E15: 8 | F15: 540.5 | G15: 0.3 | H15: 0.3 | I15: 122 | J15: 923.3 | K15: 73 | L15: 10 | M15: 928.1 | N15: 0.5 | O15: 0.3 | P15: 249 | Q15: 5.1% | T15: NWPP | U15: WECC Northwest | V15: 80.186 | W15: 290,045,161 | X15: 18.2% | Y15: 0.2% | Z15: 18.9% | AA15: 0.2% | AB15: 3.4% | AC15: 44.0% | AD15: 1.0% | AE15: 10.8% | AF15: 2.5% | AG15: 0.6% | AH15: 0.1%
A16: NWPP | B16: WECC Northwest | C16: 602.1 | D16: 56 | E16: 8 | F16: 605.9 | G16: 0.5 | H16: 0.5 | I16: 318 | J16: 1,515.7 | K16: 134 | L16: 19 | M16: 1,524.7 | N16: 45413 | O16: 45413 | P16: 790 | Q16: 5.1% | T16: NYCW | U16: NPCC NYC/Westchester | V16: 12.79 | W16: 32,721,381 | X16: 0.0% | Y16: 2.3% | Z16: 96.6% | AA16: 0.6% | AB16: 0.0% | AC16: 0.0% | AD16: 0.5% | AE16: 0.0% | AF16: 0.1% | AG16: 0.0% | AH16: 0.0%
A17: NYCW | B17: NPCC NYC/Westchester | C17: 885.2 | D17: 23 | E17: 3 | F17: 886.6 | G17: 0.2 | H17: 0.2 | I17: 28 | J17: 971.8 | K17: 21 | L17: 2 | M17: 973.0 | N17: 0.3 | O17: 0.3 | P17: 21 | Q17: 5.1% | T17: NYLI | U17: NPCC Long Island | V17: 5.885 | W17: 10,828,139 | X17: 0.0% | Y17: 6.4% | Z17: 82.7% | AA17: 4.8% | AB17: 0.0% | AC17: 0.0% | AD17: 3.9% | AE17: 0.0% | AF17: 2.3% | AG17: 0.0% | AH17: 0.0%
A18: NYLI | B18: NPCC Long Island | C18: 1,200.7 | D18: 135 | E18: 18 | F18: 1,209.3 | G18: 0.9 | H18: 0.9 | I18: 474 | J18: 1,316.7 | K18: 39 | L18: 5 | M18: 1,319.1 | N18: 0.9 | O18: 0.8 | P18: 654 | Q18: 5.1% | T18: NYUP | U18: NPCC Upstate NY | V18: 26.053 | W18: 87,177,697 | X18: 0.0% | Y18: 0.5% | Z18: 29.2% | AA18: 0.3% | AB18: 30.8% | AC18: 30.9% | AD18: 1.5% | AE18: 5.2% | AF18: 1.6% | AG18: 0.0% | AH18: 0.0%
A19: NYUP | B19: NPCC Upstate NY | C19: 274.6 | D19: 15 | E19: 2 | F19: 275.4 | G19: 0.1 | H19: 0.1 | I19: 43 | J19: 920.1 | K19: 43 | L19: 5 | M19: 922.5 | N19: 0.5 | O19: 0.3 | P19: 189 | Q19: 5.1% | T19: PRMS | U19: Puerto Rico Miscellaneous | V19: 6.405 | W19: 17,762,020 | X19: 16.7% | Y19: 48.6% | Z19: 32.3% | AA19: 0.0% | AB19: 0.0% | AC19: 0.0% | AD19: 0.0% | AE19: 0.9% | AF19: 1.6% | AG19: 0.0% | AH19: 0.0%
