Workbook

Sheet Introduction
A1: Pages | B1: Type | C1: Description
A2: Gasoline Cost | B2: Input | C2: Convert nominal dollars per gallon to 2020 dollars per kWhr
A3: Electricity Cost | B3: Input | C3: Convert nominal dollars per kWhr to 2020 dollars per kWhr
A4: Gasoline Emissions | B4: Input | C4: Convert gCO2 per MJ to kgC02 per kWhr
A5: Electricity Emissions | B5: Input | C5: Convert gCO2 per kWhr to kgC02 per kWhr
A6: ICE Efficiency | B6: Input | C6: Convert MPG to km per kWhr
A7: EV Efficiency | B7: Input | C7: Covert MJ per km to km per kWhr
A8: Production Costs | B8: Input
A9: EV Uptake

Sheet Measure conversion
A1: Base measure | B1: Target scale | C1: Adjustment
A2: Dollars (2020) | B2: Tenths of thousands dollars (2020) | C2: 1
A3: kgCO2 | B3: Tenths of tones CO2 | C3: 1
A4: Kilometres | B4: Kilometres | C4: =POW(10,0) -> 1
A5: Kilowatt hour | B5: Kilowatt hour | C5: =POW(10,0) -> 1

Sheet Fixed parameters
A1: Parameter | B1: Description | C1: Fixed value | E1: Source
A2: alpha | B2: Quality elasticity | C2: 0.5 | E2: Vibes
A3: delta_EV | B3: Depreciation rate EVs | C3: 0.0016 | D3: =$C$5>C3/(1-C3) -> TRUE | E3: Vibes
A4: delta_ICE | B4: Depreciation rate ICE cars | C4: 0.0016 | D4: =$C$5>C4/(1-C4) -> TRUE | E4: Vibes
A5: r | B5: Discount rate | C5: =POW(D5+1,1/12)-1 -> 0.0016515813 | D5: 0.02 | E5: IPCC
A6: \bar{D} | B6: Mean distance | C6: =Distance!$Q$1 -> 1119.8395 | E6: California Energy Commission
A7: \bar{\gamma} | B7: Mean WTP Emissions | C7: ='WTP Emissions and gamma'!$G$2 -> 2.0384335e-06 | E7: Hulshof, D., & Mulder, M. (2020). Willingness to Pay for CO2 Emission Reductions in Passenger Car Transport. Environmental / Resource Economics, 75(4), 899–929. https://doi.org/10.1007/s10640-020-00411-6
A8: Q^+ | B8: Quaity: Upper bound | C8: 1 | E8: Fixed
A9: Q^- | B9: Quality: Lower bound | C9: 0 | E9: Fixed
A10: \bar{Q} | B10: Quality: Mean | C10: =C9+(C8-C9)/2 -> 0.5 | E10: Endogenous
A11: C^+_EV | B11: Manufacturing Cost (EV): Upper bound | C11: ='Production costs'!$K$3 -> 58154.479 | E11: Vibes
A12: C^-_EV | B12: Manufacturing Cost (EV): Lower bound | C12: 0 | E12: Vibes
A13: \bar{C_EV} | B13: Manufacturing Cost (EV): Mean | C13: =C12+(C11-C12)/2 -> 29077.239 | E13: Endogenous
A14: C^+_ICE | B14: Manufacturing Cost (ICE): Upper bound | C14: ='Production costs'!$K$3 -> 58154.479 | E14: Paul L E Grieco, Charles Murry, Ali Yurukoglu, The Evolution of Market Power in the U.S. Automobile Industry, The Quarterly Journal of Economics, Volume 139, Issue 2, May 2024, Pages 1201–1253, https://doi.org/10.1093/qje/qjad047
A15: C^-_ICE | B15: Manufacturing Cost (ICE): Lower bound | C15: 0 | E15: Fixed
A16: \bar{C_ICE} | B16: Manufacturing Cost (ICE): Mean | C16: =C15+(C14-C15)/2 -> 29077.239 | E16: Endogenous
A17: \omega^+_EV | B17: Fuel Efficiency (EV): Upper bound | C17: ='EV Efficiency'!G7 -> 9.7337006 | E17: IPCC
A18: \omega^-_EV | B18: Fuel Efficiency (EV): Lower bound | C18: ='EV Efficiency'!G8 -> 2.7318641 | E18: IPCC
A19: \bar{\omega_EV} | B19: Fuel Efficiency (EV): Mean | C19: =C18+(C17-C18)/2 -> 6.2327824 | E19: Endogenous
A20: \omega^+_ICE | B20: Fuel Efficiency (ICE): Upper bound | C20: ='ICE Efficiency'!H7 -> 3.086983 | E20: IPCC
A21: \omega^-_ICE | B21: Fuel Efficiency (ICE): Lower bound | C21: ='ICE Efficiency'!H8 -> 0.79075426 | E21: IPCC
A22: \bar{\omega_ICE} | B22: Fuel Efficiency (ICE): Mean | C22: =C21+(C20-C21)/2 -> 1.9388686 | E22: Endogenous
A23: E_EV | B23: Manufacturing Emissions (EV) | C23: ='Production emissions'!D10 -> 14000 | E23: IPCC
A24: E_ICE | B24: Manufacturing Emissions (ICE) | C24: ='Production emissions'!D11 -> 10000 | E24: IPCC
A25: nu | B25: WTP Range | C25: ='Range WTP & Elasticity'!J4 -> 1173.6489 | E25: Ferguson, Mark, Moataz Mohamed, Christopher D. Higgins, Elnaz Abotalebi, and Pavlos Kanaroglou (2018). “How open are Canadian households to electric vehicles? A national latent class choice analysis with willingness-to-pay and metropolitan characterization”. In: Transportation Research Part D: Transport and Environment 58, pp. 208–224. issn: 1361-9209. doi: https://doi.org/10.1016/j.trd.2017.12.006.
A26: zeta | B26: Range elasticity | C26: ='Range WTP & Elasticity'!J1 -> 0.29607788 | E26: Ferguson, Mark, Moataz Mohamed, Christopher D. Higgins, Elnaz Abotalebi, and Pavlos Kanaroglou (2018). “How open are Canadian households to electric vehicles? A national latent class choice analysis with willingness-to-pay and metropolitan characterization”. In: Transportation Research Part D: Transport and Environment 58, pp. 208–224. issn: 1361-9209. doi: https://doi.org/10.1016/j.trd.2017.12.006.
A27: B_ICE | B27: Average Tank Size | C27: ='Tank size'!$E$9 -> 469.4105 | E27: ='Tank size'!B2 -> https://www.cncda.org/wp-content/uploads/Cal-Covering-4Q-20.pdf
A28: B^+_EV | B28: Battery size: Upper Bound | C28: 80 | E28: Vibes
A29: B^-_EV | B29: Battery size: Lower Bound | C29: 0 | E29: Fixed
A30: \bar{B}_EV | B30: Battery Size: Mean | C30: =C29+(C28-C29)/2 -> 40 | E30: Endogenous
A31: mu | B31: Used car dealer mark-up | C31: 1 | E31: Vibes
A32: xi_EV | B32: Price depreciation rate (EV) | C32: 0.0087 | E32: Schloter, Lukas (2022). “Empirical analysis of the depreciation of electric vehicles compared to gasoline vehicles”. In: Transport Policy 126, pp. 268–279. issn: 0967-070X. doi: https://doi.org/10.1016/j.tranpol.2022.07.021
A33: xi_ICE | B33: Price depreciation rate (ICE) | C33: 0.0116 | E33: Schloter, Lukas (2022). “Empirical analysis of the depreciation of electric vehicles compared to gasoline vehicles”. In: Transport Policy 126, pp. 268–279. issn: 0967-070X. doi: https://doi.org/10.1016/j.tranpol.2022.07.021
A34: kappa | B34: Consumer intensity of choice | C34: 1 | E34: Vibes
A35: lambda | B35: Research intensity of choice | C35: 1e-05 | E35: Vibes
A36: P^T | B36: Target callibration price | C36: ='Production costs'!F3*'Measure conversion'!C2 -> 39293.567 | E36: Paul L E Grieco, Charles Murry, Ali Yurukoglu, The Evolution of Market Power in the U.S. Automobile Industry, The Quarterly Journal of Economics, Volume 139, Issue 2, May 2024, Pages 1201–1253, https://doi.org/10.1093/qje/qjad047
A37: \bar{c}_ICE | B37: Average gasoline cost/KWhr | C37: =AVERAGE('Gasoline cost'!$H$14:$H$277) -> 0.111969 | E37: ='Gasoline cost'!B2 -> https://www.eia.gov/petroleum/gasdiesel/
A38: \bar{e}_ICE | B38: Average gasoline emissions/KWhr | C38: ='Gasoline Emissions'!E2 -> 0.33117351 | E38: ='Gasoline Emissions'!B6 -> https://www.ipcc.ch/report/ar6/wg3/downloads/report/IPCC_AR6_WGIII_Chapter10.pdf
A39: \bar{c}_EV | B39: Average electricity cost/KWhr | C39: ='Electricity cost'!B4 -> 0.17248706 | E39: ='Electricity cost'!B2 -> https://www.eia.gov/opendata/browser/electricity/retail-sales
A40: \bar{e}_EV | B40: Average electricity emissions/KWhr | C40: ='Electricity emissions'!B5 -> 0.27196594 | E40: ='Electricity emissions'!B4 -> https://ember-energy.org/data/us-electricity-data-explorer/
...

Sheet EV Sales
A1: Year | B1: Percentatge | C1: BEV | D1: PHEV | E1: FCEV | F1: Sum | G1: Perc BEV
A2: 2020 | B2: 7.78 | C2: 10600 | D2: 38000 | E2: 1000 | F2: 49600 | G2: 1.662661
A3: 2021 | B3: 12.66 | C3: 160000 | D3: 53000 | E3: 3000 | F3: 216000 | G3: 9.377778
A4: 2022 | B4: 19.49 | C4: 262076 | D4: 43689 | E4: 2503 | F4: 308268 | G4: 16.56955
A5: 2023 | B5: 25.02 | C5: 374688 | D5: 63496 | E5: 3119 | F5: 441303 | G5: 21.24321

Sheet CPI
A1: Type: | B1: Input | C1: Date | D1: California Weighted Average | E1: 2020 real CPI Adjusted
A2: Source: | B2: https://dof.ca.gov/forecasting/economics/economic-indicators/inflation/ | C2: 36526 | D2: NA | E2: 0.60618524
A3: Measure: | B3: Consumer Price Index | C3: 36557 | D3: 172 | E3: 0.60618524
A4: Description: | B4: California CPI is a population weighted average across multiple local CPIs (Los Angeles area monthly, the Riverside area bimonthly, San Diego county bimonthly, the San Francisco area bimonthly) | C4: 36586 | D4: NA | E4: 0.60898886
C5: 36617 | D5: 173.6 | E5: 0.61179249
C6: 36647 | D6: NA | E6: 0.61249912
A7: Conversions: | B7: Divide through by CPI index on 2020-01-01 | C7: 36678 | D7: 174 | E7: 0.61320575
C8: 36708 | D8: NA | E8: 0.61611687
A9: Steps: | B9: 1. Interpolate data where missing months | C9: 36739 | D9: 175.6 | E9: 0.61902798
B10: 2. For 01/01/2000 use value for 01/02/2000 | C10: 36770 | D10: NA | E10: 0.6219109
C11: 36800 | D11: 177.3 | E11: 0.62479383
C12: 36831 | D12: NA | E12: 0.62482907
C13: 36861 | D13: 177.3 | E13: 0.62486431
C14: 36892 | D14: NA | E14: 0.62929442
C15: 36923 | D15: 179.8 | E15: 0.63372454
C16: 36951 | D16: NA | E16: 0.63584267
C17: 36982 | D17: 181 | E17: 0.63796081
C18: 37012 | D18: NA | E18: 0.64174068
C19: 37043 | D19: 183.2 | E19: 0.64552055
C20: 37073 | D20: NA | E20: 0.6449778
C21: 37104 | D21: 182.9 | E21: 0.64443505
C22: 37135 | D22: NA | E22: 0.64470995
C23: 37165 | D23: 183 | E23: 0.64498484
C24: 37196 | D24: NA | E24: 0.64292134
C25: 37226 | D25: 181.8 | E25: 0.64085783
C26: 37257 | D26: NA | E26: 0.64485621
C27: 37288 | D27: 184.1 | E27: 0.64885459
C28: 37316 | D28: NA | E28: 0.65233841
C29: 37347 | D29: 186.1 | E29: 0.65582223
C30: 37377 | D30: NA | E30: 0.65557553
C31: 37408 | D31: 185.9 | E31: 0.65532882
C32: 37438 | D32: NA | E32: 0.65681962
C33: 37469 | D33: 186.8 | E33: 0.65831043
C34: 37500 | D34: NA | E34: 0.6596021
C35: 37530 | D35: 187.5 | E35: 0.66089378
C36: 37561 | D36: NA | E36: 0.66027349
C37: 37591 | D37: 187.2 | E37: 0.6596532
C38: 37622 | D38: NA | E38: 0.66555826
C39: 37653 | D39: 190.5 | E39: 0.67146331
C40: 37681 | D40: NA | E40: 0.67255939
...

Sheet Income distribution
A1: Type: | B1: Input | D1: tem | E1: All Consumer Units | F1: Lowest 20 Percent | G1: Second 20 Percent | H1: Third 20 Percent | I1: Fourth 20 Percent | J1: Highest 20 Percent | L1: GINI | M1: =SUM(F4:J8)/(2*E2*SUMPRODUCT(F2:J2,F3:J3)) -> 0.45109751 | O1: X-value | P1: Income
A2: Source: | B2: https://www.bls.gov/cex/tables/geographic/mean/cu-state-ca-income-quintiles-before-taxes-2-year-average-2020.htm | D2: Number of Consumer Units (in thousands) | E2: 14248388 | F2: 2735227 | G2: 2774747 | H2: 2943249 | I2: 2945121 | J2: 2850043 | L2: n2 * \bar{x} | M2: =POW(E2,2)*E3 -> 2.01032e+19 | O2: 0.001 | P2: =_xlfn.LOGNORM.INV(O2,$B$19,$B$20) -> 4275.2508
A3: Measure: | B3: Quintiles of income California 2020 | D3: Income before taxes | E3: 99022.5 | F3: 13584.06 | G3: 39369.1 | H3: 68070.28 | I3: 112527.22 | J3: 257105.69 | L3: n*\sum_i x | M3: =E2*SUMPRODUCT(F2:J2,F3:J3) -> 2.01032e+19 | O3: =O2+0.001 -> 0.002 | P3: =_xlfn.LOGNORM.INV(O3,$B$19,$B$20) -> 5204.024
E4: Lowest 20 Percent | F4: =ABS(F$3-INDEX($F$3:$J$3,MATCH($E4,$F$1:$J$1,0)))*F$2*INDEX($F$2:$J$2,MATCH($E4,$F$1:$J$1,0)) -> 0 | G4: =ABS(G$3-INDEX($F$3:$J$3,MATCH($E4,$F$1:$J$1,0)))*G$2*INDEX($F$2:$J$2,MATCH($E4,$F$1:$J$1,0)) -> 1.95697e+17 | H4: =ABS(H$3-INDEX($F$3:$J$3,MATCH($E4,$F$1:$J$1,0)))*H$2*INDEX($F$2:$J$2,MATCH($E4,$F$1:$J$1,0)) -> 4.38639e+17 | I4: =ABS(I$3-INDEX($F$3:$J$3,MATCH($E4,$F$1:$J$1,0)))*I$2*INDEX($F$2:$J$2,MATCH($E4,$F$1:$J$1,0)) -> 7.97044e+17 | J4: =ABS(J$3-INDEX($F$3:$J$3,MATCH($E4,$F$1:$J$1,0)))*J$2*INDEX($F$2:$J$2,MATCH($E4,$F$1:$J$1,0)) -> 1.89838e+18 | L4: Sum_Diff | M4: =SUM(F4:J8) -> 1.8137e+19 | O4: =O3+0.001 -> 0.003 | P4: =_xlfn.LOGNORM.INV(O4,$B$19,$B$20) -> 5872.5842
E5: Second 20 Percent | F5: =ABS(F$3-INDEX($F$3:$J$3,MATCH($E5,$F$1:$J$1,0)))*F$2*INDEX($F$2:$J$2,MATCH($E5,$F$1:$J$1,0)) -> 1.95697e+17 | G5: =ABS(G$3-INDEX($F$3:$J$3,MATCH($E5,$F$1:$J$1,0)))*G$2*INDEX($F$2:$J$2,MATCH($E5,$F$1:$J$1,0)) -> 0 | H5: =ABS(H$3-INDEX($F$3:$J$3,MATCH($E5,$F$1:$J$1,0)))*H$2*INDEX($F$2:$J$2,MATCH($E5,$F$1:$J$1,0)) -> 2.34396e+17 | I5: =ABS(I$3-INDEX($F$3:$J$3,MATCH($E5,$F$1:$J$1,0)))*I$2*INDEX($F$2:$J$2,MATCH($E5,$F$1:$J$1,0)) -> 5.97846e+17 | J5: =ABS(J$3-INDEX($F$3:$J$3,MATCH($E5,$F$1:$J$1,0)))*J$2*INDEX($F$2:$J$2,MATCH($E5,$F$1:$J$1,0)) -> 1.72189e+18 | O5: =O4+0.001 -> 0.004 | P5: =_xlfn.LOGNORM.INV(O5,$B$19,$B$20) -> 6417.4407
E6: Third 20 Percent | F6: =ABS(F$3-INDEX($F$3:$J$3,MATCH($E6,$F$1:$J$1,0)))*F$2*INDEX($F$2:$J$2,MATCH($E6,$F$1:$J$1,0)) -> 4.38639e+17 | G6: =ABS(G$3-INDEX($F$3:$J$3,MATCH($E6,$F$1:$J$1,0)))*G$2*INDEX($F$2:$J$2,MATCH($E6,$F$1:$J$1,0)) -> 2.34396e+17 | H6: =ABS(H$3-INDEX($F$3:$J$3,MATCH($E6,$F$1:$J$1,0)))*H$2*INDEX($F$2:$J$2,MATCH($E6,$F$1:$J$1,0)) -> 0 | I6: =ABS(I$3-INDEX($F$3:$J$3,MATCH($E6,$F$1:$J$1,0)))*I$2*INDEX($F$2:$J$2,MATCH($E6,$F$1:$J$1,0)) -> 3.85363e+17 | J6: =ABS(J$3-INDEX($F$3:$J$3,MATCH($E6,$F$1:$J$1,0)))*J$2*INDEX($F$2:$J$2,MATCH($E6,$F$1:$J$1,0)) -> 1.5857e+18 | O6: =O5+0.001 -> 0.005 | P6: =_xlfn.LOGNORM.INV(O6,$B$19,$B$20) -> 6887.4048
E7: Fourth 20 Percent | F7: =ABS(F$3-INDEX($F$3:$J$3,MATCH($E7,$F$1:$J$1,0)))*F$2*INDEX($F$2:$J$2,MATCH($E7,$F$1:$J$1,0)) -> 7.97044e+17 | G7: =ABS(G$3-INDEX($F$3:$J$3,MATCH($E7,$F$1:$J$1,0)))*G$2*INDEX($F$2:$J$2,MATCH($E7,$F$1:$J$1,0)) -> 5.97846e+17 | H7: =ABS(H$3-INDEX($F$3:$J$3,MATCH($E7,$F$1:$J$1,0)))*H$2*INDEX($F$2:$J$2,MATCH($E7,$F$1:$J$1,0)) -> 3.85363e+17 | I7: =ABS(I$3-INDEX($F$3:$J$3,MATCH($E7,$F$1:$J$1,0)))*I$2*INDEX($F$2:$J$2,MATCH($E7,$F$1:$J$1,0)) -> 0 | J7: =ABS(J$3-INDEX($F$3:$J$3,MATCH($E7,$F$1:$J$1,0)))*J$2*INDEX($F$2:$J$2,MATCH($E7,$F$1:$J$1,0)) -> 1.21355e+18 | O7: =O6+0.001 -> 0.006 | P7: =_xlfn.LOGNORM.INV(O7,$B$19,$B$20) -> 7306.2513
E8: Highest 20 Percent | F8: =ABS(F$3-INDEX($F$3:$J$3,MATCH($E8,$F$1:$J$1,0)))*F$2*INDEX($F$2:$J$2,MATCH($E8,$F$1:$J$1,0)) -> 1.89838e+18 | G8: =ABS(G$3-INDEX($F$3:$J$3,MATCH($E8,$F$1:$J$1,0)))*G$2*INDEX($F$2:$J$2,MATCH($E8,$F$1:$J$1,0)) -> 1.72189e+18 | H8: =ABS(H$3-INDEX($F$3:$J$3,MATCH($E8,$F$1:$J$1,0)))*H$2*INDEX($F$2:$J$2,MATCH($E8,$F$1:$J$1,0)) -> 1.5857e+18 | I8: =ABS(I$3-INDEX($F$3:$J$3,MATCH($E8,$F$1:$J$1,0)))*I$2*INDEX($F$2:$J$2,MATCH($E8,$F$1:$J$1,0)) -> 1.21355e+18 | J8: =ABS(J$3-INDEX($F$3:$J$3,MATCH($E8,$F$1:$J$1,0)))*J$2*INDEX($F$2:$J$2,MATCH($E8,$F$1:$J$1,0)) -> 0 | O8: =O7+0.001 -> 0.007 | P8: =_xlfn.LOGNORM.INV(O8,$B$19,$B$20) -> 7687.5716
O9: =O8+0.001 -> 0.008 | P9: =_xlfn.LOGNORM.INV(O9,$B$19,$B$20) -> 8039.9543
O10: =O9+0.001 -> 0.009 | P10: =_xlfn.LOGNORM.INV(O10,$B$19,$B$20) -> 8369.2151
A11: Source: | B11: "B19082: Shares of aggregate household income by quintiles". data.census.gov. Retrieved 2022-02-09. | D11: California | E11: 1st Quintile | F11: 2nd quintile | G11: 3rd quintile | H11: 4th quintile | I11: 5th quintile | J11: Of which top 5% | O11: =O10+0.001 -> 0.01 | P11: =_xlfn.LOGNORM.INV(O11,$B$19,$B$20) -> 8679.4975
A12: URL: | B12: https://data.census.gov/table/ACSDT1Y2019.B19082?g=040XX00US51,50,11,12,53,10,54,15,16,13,19,17,18,40,41,44,01,45,42,48,04,49,05,46,02,47,08,09,06,30,33,34,31,32,37,38,35,36,39,22,23,20,21,26,27,24,25,28,29,72,55,56_010XX00US&moe=false&tp=true&tid=ACSDT1Y2019.B19082 | D12: Mean income (2019) | E12: 16981 | F12: 47103 | G12: 80693 | H12: 127666 | I12: 295369 | J12: 531014 | O12: =O11+0.001 -> 0.011 | P12: =_xlfn.LOGNORM.INV(O12,$B$19,$B$20) -> 8973.8706
A13: Gini coefficient (2019) | B13: 0.4866 | D13: Share | E13: 0.0299 | F13: 0.083 | G13: 0.1421 | H13: 0.2248 | I13: 0.5202 | J13: 0.2338 | O13: =O12+0.001 -> 0.012 | P13: =_xlfn.LOGNORM.INV(O13,$B$19,$B$20) -> 9254.6794
A14: 2020 conversion factor | B14: 0.99596109 | D14: Mean income (2020) | E14: =E12/$B$14 -> 17049.863 | F14: =F12/$B$14 -> 47294.016 | G14: =G12/$B$14 -> 81020.233 | H14: =H12/$B$14 -> 128183.72 | I14: =I12/$B$14 -> 296566.81 | J14: =J12/$B$14 -> 533167.41 | O14: =O13+0.001 -> 0.013 | P14: =_xlfn.LOGNORM.INV(O14,$B$19,$B$20) -> 9523.7607
O15: =O14+0.001 -> 0.014 | P15: =_xlfn.LOGNORM.INV(O15,$B$19,$B$20) -> 9782.5838
O16: =O15+0.001 -> 0.015 | P16: =_xlfn.LOGNORM.INV(O16,$B$19,$B$20) -> 10032.345
A17: Log-normal distribution parameters | O17: =O16+0.001 -> 0.016 | P17: =_xlfn.LOGNORM.INV(O17,$B$19,$B$20) -> 10274.031
A18: n | B18: I | O18: =O17+0.001 -> 0.017 | P18: =_xlfn.LOGNORM.INV(O18,$B$19,$B$20) -> 10508.471
A19: mu | B19: 11.225243 | O19: =O18+0.001 -> 0.018 | P19: =_xlfn.LOGNORM.INV(O19,$B$19,$B$20) -> 10736.363
A20: sigma | B20: 0.927 | O20: =O19+0.001 -> 0.019 | P20: =_xlfn.LOGNORM.INV(O20,$B$19,$B$20) -> 10958.307
O21: =O20+0.001 -> 0.02 | P21: =_xlfn.LOGNORM.INV(O21,$B$19,$B$20) -> 11174.818
O22: =O21+0.001 -> 0.021 | P22: =_xlfn.LOGNORM.INV(O22,$B$19,$B$20) -> 11386.346
O23: =O22+0.001 -> 0.022 | P23: =_xlfn.LOGNORM.INV(O23,$B$19,$B$20) -> 11593.284
O24: =O23+0.001 -> 0.023 | P24: =_xlfn.LOGNORM.INV(O24,$B$19,$B$20) -> 11795.977
O25: =O24+0.001 -> 0.024 | P25: =_xlfn.LOGNORM.INV(O25,$B$19,$B$20) -> 11994.732
O26: =O25+0.001 -> 0.025 | P26: =_xlfn.LOGNORM.INV(O26,$B$19,$B$20) -> 12189.824
O27: =O26+0.001 -> 0.026 | P27: =_xlfn.LOGNORM.INV(O27,$B$19,$B$20) -> 12381.496
O28: =O27+0.001 -> 0.027 | P28: =_xlfn.LOGNORM.INV(O28,$B$19,$B$20) -> 12569.97
O29: =O28+0.001 -> 0.028 | P29: =_xlfn.LOGNORM.INV(O29,$B$19,$B$20) -> 12755.443
O30: =O29+0.001 -> 0.029 | P30: =_xlfn.LOGNORM.INV(O30,$B$19,$B$20) -> 12938.096
O31: =O30+0.001 -> 0.03 | P31: =_xlfn.LOGNORM.INV(O31,$B$19,$B$20) -> 13118.093
O32: =O31+0.001 -> 0.031 | P32: =_xlfn.LOGNORM.INV(O32,$B$19,$B$20) -> 13295.584
... O1000: =O999+0.001 -> 0.999 | P1000: =_xlfn.LOGNORM.INV(O1000,$B$19,$B$20) -> 1315712.3

Sheet Plots_TimeSeries
A1: Month | B1: Year | C1: Date | D1: Monthly California Regular Reformulated Retail Gasoline Prices (Dollars per KWh) | E1: Monthly California Residential Electricity Price (Dollars per KWh) | G1: date | H1: Gasoline kgCO2 per KWh | I1: Electricity kgCO2 per KWh
A2: Jan | B2: 2000 | C2: =A2&"/"&B2 -> Jan/2000 | D2: 0.041093093 | E2: =$E$14 -> 0.1089 | G2: =A14&"/"&B14 -> Jan/2001 | H2: 0.33117351 | I2: 0.34327
A3: Feb | B3: 2000 | C3: =A3&"/"&B3 -> Feb/2000 | D3: 0.043475976 | E3: =$E$14 -> 0.1089 | G3: =A15&"/"&B15 -> Feb/2001 | H3: 0.33117351 | I3: 0.34356
A4: Mar | B4: 2000 | C4: =A4&"/"&B4 -> Mar/2000 | D4: 0.052612613 | E4: =$E$14 -> 0.1089 | G4: =A16&"/"&B16 -> Mar/2001 | H4: 0.33117351 | I4: 0.32511
A5: Apr | B5: 2000 | C5: =A5&"/"&B5 -> Apr/2000 | D5: 0.05256006 | E5: =$E$14 -> 0.1089 | G5: =A17&"/"&B17 -> Apr/2001 | H5: 0.33117351 | I5: 0.32078
A6: May | B6: 2000 | C6: =A6&"/"&B6 -> May/2000 | D6: 0.04957958 | E6: =$E$14 -> 0.1089 | G6: =A18&"/"&B18 -> May/2001 | H6: 0.33117351 | I6: 0.31855
A7: Jun | B7: 2000 | C7: =A7&"/"&B7 -> Jun/2000 | D7: 0.048693694 | E7: =$E$14 -> 0.1089 | G7: =A19&"/"&B19 -> Jun/2001 | H7: 0.33117351 | I7: 0.28845
A8: Jul | B8: 2000 | C8: =A8&"/"&B8 -> Jul/2000 | D8: 0.051363363 | E8: =$E$14 -> 0.1089 | G8: =A20&"/"&B20 -> Jul/2001 | H8: 0.33117351 | I8: 0.30122
A9: Aug | B9: 2000 | C9: =A9&"/"&B9 -> Aug/2000 | D9: 0.050322823 | E9: =$E$14 -> 0.1089 | G9: =A21&"/"&B21 -> Aug/2001 | H9: 0.33117351 | I9: 0.30837
A10: Sep | B10: 2000 | C10: =A10&"/"&B10 -> Sep/2000 | D10: 0.054827327 | E10: =$E$14 -> 0.1089 | G10: =A22&"/"&B22 -> Sep/2001 | H10: 0.33117351 | I10: 0.30442
A11: Oct | B11: 2000 | C11: =A11&"/"&B11 -> Oct/2000 | D11: 0.054414414 | E11: =$E$14 -> 0.1089 | G11: =A23&"/"&B23 -> Oct/2001 | H11: 0.33117351 | I11: 0.30442
A12: Nov | B12: 2000 | C12: =A12&"/"&B12 -> Nov/2000 | D12: 0.053033033 | E12: =$E$14 -> 0.1089 | G12: =A24&"/"&B24 -> Nov/2001 | H12: 0.33117351 | I12: 0.28881
A13: Dec | B13: 2000 | C13: =A13&"/"&B13 -> Dec/2000 | D13: 0.050405405 | E13: =$E$14 -> 0.1089 | G13: =A25&"/"&B25 -> Dec/2001 | H13: 0.33117351 | I13: 0.2853
A14: Jan | B14: 2001 | C14: =A14&"/"&B14 -> Jan/2001 | D14: 0.048072072 | E14: 0.1089 | G14: =A26&"/"&B26 -> Jan/2002 | H14: 0.33117351 | I14: 0.26315
A15: Feb | B15: 2001 | C15: =A15&"/"&B15 -> Feb/2001 | D15: 0.049166667 | E15: 0.1114 | G15: =A27&"/"&B27 -> Feb/2002 | H15: 0.33117351 | I15: 0.26665
A16: Mar | B16: 2001 | C16: =A16&"/"&B16 -> Mar/2001 | D16: 0.050840841 | E16: 0.1129 | G16: =A28&"/"&B28 -> Mar/2002 | H16: 0.33117351 | I16: 0.27642
A17: Apr | B17: 2001 | C17: =A17&"/"&B17 -> Apr/2001 | D17: 0.053831832 | E17: 0.1114 | G17: =A29&"/"&B29 -> Apr/2002 | H17: 0.33117351 | I17: 0.23476
A18: May | B18: 2001 | C18: =A18&"/"&B18 -> May/2001 | D18: 0.058483483 | E18: 0.1197 | G18: =A30&"/"&B30 -> May/2002 | H18: 0.33117351 | I18: 0.23788
A19: Jun | B19: 2001 | C19: =A19&"/"&B19 -> Jun/2001 | D19: 0.05786036 | E19: 0.1287 | G19: =A31&"/"&B31 -> Jun/2002 | H19: 0.33117351 | I19: 0.27519
A20: Jul | B20: 2001 | C20: =A20&"/"&B20 -> Jul/2001 | D20: 0.053153153 | E20: 0.1305 | G20: =A32&"/"&B32 -> Jul/2002 | H20: 0.33117351 | I20: 0.29284
A21: Aug | B21: 2001 | C21: =A21&"/"&B21 -> Aug/2001 | D21: 0.046801802 | E21: 0.128 | G21: =A33&"/"&B33 -> Aug/2002 | H21: 0.33117351 | I21: 0.28859
A22: Sep | B22: 2001 | C22: =A22&"/"&B22 -> Sep/2001 | D22: 0.04993994 | E22: 0.1287 | G22: =A34&"/"&B34 -> Sep/2002 | H22: 0.33117351 | I22: 0.29374
A23: Oct | B23: 2001 | C23: =A23&"/"&B23 -> Oct/2001 | D23: 0.046426426 | E23: 0.1249 | G23: =A35&"/"&B35 -> Oct/2002 | H23: 0.33117351 | I23: 0.28099
A24: Nov | B24: 2001 | C24: =A24&"/"&B24 -> Nov/2001 | D24: 0.040758258 | E24: 0.1212 | G24: =A36&"/"&B36 -> Nov/2002 | H24: 0.33117351 | I24: 0.29266
A25: Dec | B25: 2001 | C25: =A25&"/"&B25 -> Dec/2001 | D25: 0.034774775 | E25: 0.1226 | G25: =A37&"/"&B37 -> Dec/2002 | H25: 0.33117351 | I25: 0.28418
... A287: Oct | B287: 2023 | C287: =A287&"/"&B287 -> Oct/2023 | D287: 0.16332132 | E287: 0.3178 | G287: =A299&"/"&B299 -> Oct/2024 | H287: 0.33117351 | I287: 0.22789
A288: Nov | B288: 2023 | C288: =A288&"/"&B288 -> Nov/2023 | D288: 0.14490991 | E288: 0.2954
A289: Dec | B289: 2023 | C289: =A289&"/"&B289 -> Dec/2023 | D289: 0.13350601 | E289: 0.2912
A290: Jan | B290: 2024 | C290: =A290&"/"&B290 -> Jan/2024 | D290: 0.1311952 | E290: 0.2949
A291: Feb | B291: 2024 | C291: =A291&"/"&B291 -> Feb/2024 | D291: 0.13284535 | E291: 0.3124
A292: Mar | B292: 2024 | C292: =A292&"/"&B292 -> Mar/2024 | D292: 0.14173423 | E292: 0.3248
A293: Apr | B293: 2024 | C293: =A293&"/"&B293 -> Apr/2024 | D293: 0.15451051 | E293: 0.3426
A294: May | B294: 2024 | C294: =A294&"/"&B294 -> May/2024 | D294: 0.15029279 | E294: 0.343
A295: Jun | B295: 2024 | C295: =A295&"/"&B295 -> Jun/2024 | D295: 0.14001502 | E295: 0.3299
A296: Jul | B296: 2024 | C296: =A296&"/"&B296 -> Jul/2024 | D296: 0.13425225 | E296: 0.3255
A297: Aug | B297: 2024 | C297: =A297&"/"&B297 -> Aug/2024 | D297: 0.13009009 | E297: 0.3105
A298: Sep | B298: 2024 | C298: =A298&"/"&B298 -> Sep/2024 | D298: 0.13377177 | E298: 0.3164
A299: Oct | B299: 2024 | C299: =A299&"/"&B299 -> Oct/2024 | D299: 0.13189189 | E299: 0.3022
A300: Nov | B300: 2024 | C300: =A300&"/"&B300 -> Nov/2024 | D300: 0.1271997 | E300: =E299 -> 0.3022
A301: Dec | B301: 2024 | C301: =A301&"/"&B301 -> Dec/2024 | D301: 0.1238018 | E301: =E300 -> 0.3022
...

Sheet Distance
A1: Type: | B1: Input | D1: Self-reported annual vehicle miles traveled (VMT) | E1: Ownership | F1: Fuel Type | G1: Age | H1: Mileage | I1: Count | J1: Km per year (upper bound) | K1: km per month (upper) | L1: km per month (midpoint) | M1: Proportion | N1: Model scale /month | P1: Mean distance | Q1: =SUMPRODUCT(M2:M7,N2:N7) -> 1119.8395
A2: Source: | B2: https://www.energy.ca.gov/data-reports/surveys/california-vehicle-survey/vehicle-miles-traveled-fuel-type | E2: Household | F2: ICE | G2: 0-1 years old | H2: <5,000 | I2: 145 | J2: 8046.7 | K2: =J2/12 -> 670.55833 | L2: =K2/2 -> 335.27917 | M2: 0.41334205 | N2: =L2*'Measure conversion'!$C$4 -> 335.27917
E3: Household | F3: ICE | G3: 0-1 years old | H3: 5,000-9,999 | I3: 231 | J3: 16093.4 | K3: =J3/12 -> 1341.1167 | L3: =(K3 + K2)/2 -> 1005.8375 | M3: 0.29463702 | N3: =L3*'Measure conversion'!$C$4 -> 1005.8375
A4: Measure: | B4: km per month | E4: Household | F4: ICE | G4: 0-1 years old | H4: 10,000-14,999 | I4: 207 | J4: 24138.551 | K4: =J4/12 -> 2011.5459 | L4: =(K4 + K3)/2 -> 1676.3313 | M4: 0.18443427 | N4: =L4*'Measure conversion'!$C$4 -> 1676.3313
E5: Household | F5: ICE | G5: 0-1 years old | H5: 15,000-19,999 | I5: 62 | J5: 32186.88 | K5: =J5/12 -> 2682.24 | L5: =(K5 + K4)/2 -> 2346.8929 | M5: 0.038587312 | N5: =L5*'Measure conversion'!$C$4 -> 2346.8929
E6: Household | F6: ICE | G6: 0-1 years old | H6: 20,000-24,999 | I6: 31 | J6: 40231.991 | K6: =J6/12 -> 3352.6659 | L6: =(K6 + K5)/2 -> 3017.4529 | M6: 0.030739045 | N6: =L6*'Measure conversion'!$C$4 -> 3017.4529
A7: Secndary Source: | B7: https://www.eia.gov/totalenergy/data/browser/?tbl=T01.09#/?f=A&start=2016&end=2022&charted=1-2-3-5-6 | E7: Household | F7: ICE | G7: 0-1 years old | H7: 25,000+ | I7: 29 | J7: 40231.9907 + | K7: 5028.99 | L7: 5028.99 | M7: 0.038260301 | N7: =L7*'Measure conversion'!$C$4 -> 5028.99
H8: total respondents | I8: =SUM(I2:I7) -> 705 | K8: Assume 50% more than the max | L8: Assume 50% more than the max
A9: Conversions
A10: km to miles: | B10: 1.60934
G11: Age | H11: Mileage | I11: Proportion | J11: counts | K11: Assume 10+years is 15 years
G12: 10+years | H12: <5,000 | I12: 0.41334205 | J12: =ROUND(I12*I18,0) -> 1264
G13: 10+years | H13: 5,000-9,999 | I13: 0.29463702 | J13: =ROUND(I13*I18,0) -> 901
G14: 10+years | H14: 10,000-14,999 | I14: 0.18443427 | J14: =ROUND(I14*I18,0) -> 564
G15: 10+years | H15: 15,000-19,999 | I15: 0.038587312 | J15: =ROUND(I15*I18,0) -> 118
G16: 10+years | H16: 20,000-24,999 | I16: 0.030739045 | J16: =ROUND(I16*I18,0) -> 94
G17: 10+years | H17: 25,000+ | I17: 0.038260301 | J17: =ROUND(I17*I18,0) -> 117
H18: total respondents | I18: 3058 | J18: =sum(J12:J17) -> 3058

Sheet WTP Emissions and gamma
A1: Type: | B1: Input | C1: WTP (Euros Dec 2017 / kgCO2) /km | D1: WTP (Dollars Dec 2017 / kgCO2) /km | E1: WTP (Dollars 2020 / kgCO2) /km | F1: ="WTP "&'Measure conversion'!$B$2&" / "&'Measure conversion'!$B$3 & " / km" -> WTP Tenths of thousands dollars (2020) / Tenths of tones CO2 / km | G1: Mean gamma | I1: X-value | J1: Random Values | L1: =L2-$L$6/5 -> 0 | M1: =COUNTIF($J$2:$J$1000,"<"&L1) -> 116 | O1: Mean | P1: =AVERAGE(J2:J1000) -> 2.1342306e-06
A2: Source: | B2: Hulshof, D., & Mulder, M. (2020). Willingness to Pay for CO2 Emission Reductions in Passenger Car Transport. Environmental / Resource Economics, 75(4), 899–929. https://doi.org/10.1007/s10640-020-00411-6 | C2: 36.7 | D2: =C2*B6 -> 43.673 | E2: =D2/B11 -> 46.646654 | F2: =E2*'Measure conversion'!$C$2/'Measure conversion'!$C$3 -> 46.646654 | G2: =(F2*($B$18-$B$19-$B$18*$B$19)/($B$17*(1+$B$18)*(1-$B$19))) -> 2.0384335e-06 | I2: 0.001 | J2: =MAX(NORMINV(I2,$G$2,$G$5),0) -> 0 | L2: =L3-$L$6/5 -> 4.076867e-07 | M2: =COUNTIFS($J$2:$J$1000,"<"&L2,$J$2:J$1000,">="&L1) -> 54 | O2: SD | P2: =STDEV(J2:J1000) -> 1.5367785e-06
A3: Measure: | B3: WTP to reduce driving emissions with 1 g per kilometer in 2020 dollars | I3: =I2+0.001 -> 0.002 | J3: =MAX(NORMINV(I3,$G$2,$G$5),0) -> 0 | L3: =L4-$L$6/5 -> 8.153734e-07 | M3: =COUNTIFS($J$2:$J$1000,"<"&L3,$J$2:J$1000,">="&L2) -> 67
C4: SD WTP Euros Dec 2017 / kgCO2 | D4: SD WTP Dollars Dec 2017 / kgCO2 | E4: SD WTP Dollars 2020 / kgCO2 | F4: ="SD "&'Measure conversion'!$B$2&" / "&'Measure conversion'!$B$3 -> SD Tenths of thousands dollars (2020) / Tenths of tones CO2 | G4: SD gamma | I4: =I3+0.001 -> 0.003 | J4: =MAX(NORMINV(I4,$G$2,$G$5),0) -> 0 | L4: =L5-$L$6/5 -> 1.2230601e-06 | M4: =COUNTIFS($J$2:$J$1000,"<"&L4,$J$2:J$1000,">="&L3) -> 79
C5: 30.81 | D5: =C5*B6 -> 36.6639 | E5: =D5/B11 -> 39.160311 | F5: =E5*'Measure conversion'!$C$2/'Measure conversion'!$C$3 -> 39.160311 | G5: =(F5*($B$18-$B$19-$B$18*$B$19)/($B$17*(1+$B$18)*(1-$B$19))) -> 1.7112844e-06 | I5: =I4+0.001 -> 0.004 | J5: =MAX(NORMINV(I5,$G$2,$G$5),0) -> 0 | L5: =L6-$L$6/5 -> 1.6307468e-06 | M5: =COUNTIFS($J$2:$J$1000,"<"&L5,$J$2:J$1000,">="&L4) -> 89
A6: Exhcange rate 1/12/2017, dollars per euro | B6: 1.19 | I6: =I5+0.001 -> 0.005 | J6: =MAX(NORMINV(I6,$G$2,$G$5),0) -> 0 | L6: =$G$2 -> 2.0384335e-06 | M6: =COUNTIFS($J$2:$J$1000,"<"&L6,$J$2:J$1000,">="&L5) -> 94
A7: Source | B7: https://www.xe.com/currencycharts/?from=EUR/to=USD/view=10Y | I7: =I6+0.001 -> 0.006 | J7: =MAX(NORMINV(I7,$G$2,$G$5),0) -> 0 | L7: =L6+$L$6/5 -> 2.4461202e-06 | M7: =COUNTIFS($J$2:$J$1000,"<"&L7,$J$2:J$1000,">="&L6) -> 95
A8: Issue: Took a single day exchange rate but the issue here is that we dont know when the survey was taken within the month | I8: =I7+0.001 -> 0.007 | J8: =MAX(NORMINV(I8,$G$2,$G$5),0) -> 0 | L8: =L7+$L$6/5 -> 2.8538069e-06 | M8: =COUNTIFS($J$2:$J$1000,"<"&L8,$J$2:J$1000,">="&L7) -> 89
A9: CentERpanel in December 2017. | I9: =I8+0.001 -> 0.008 | J9: =MAX(NORMINV(I9,$G$2,$G$5),0) -> 0 | L9: =L8+$L$6/5 -> 3.2614936e-06 | M9: =COUNTIFS($J$2:$J$1000,"<"&L9,$J$2:J$1000,">="&L8) -> 79
I10: =I9+0.001 -> 0.009 | J10: =MAX(NORMINV(I10,$G$2,$G$5),0) -> 0 | L10: =L9+$L$6/5 -> 3.6691803e-06 | M10: =COUNTIFS($J$2:$J$1000,"<"&L10,$J$2:J$1000,">="&L9) -> 67
A11: CPI 2020 dollars to Dec 2017 | B11: 0.9362515 | I11: =I10+0.001 -> 0.01 | J11: =MAX(NORMINV(I11,$G$2,$G$5),0) -> 0 | L11: =L10+$L$6/5 -> 4.076867e-06 | M11: =COUNTIFS($J$2:$J$1000,"<"&L11,$J$2:J$1000,">="&L10) -> 54
A12: source | B12: https://dof.ca.gov/forecasting/economics/economic-indicators/inflation/ | I12: =I11+0.001 -> 0.011 | J12: =MAX(NORMINV(I12,$G$2,$G$5),0) -> 0 | L12: =L11+$L$6/5 -> 4.4845537e-06 | M12: =COUNTIFS($J$2:$J$1000,"<"&L12,$J$2:J$1000,">="&L11) -> 40
I13: =I12+0.001 -> 0.012 | J13: =MAX(NORMINV(I13,$G$2,$G$5),0) -> 0 | L13: =L12+$L$6/5 -> 4.8922404e-06 | M13: =COUNTIFS($J$2:$J$1000,"<"&L13,$J$2:J$1000,">="&L12) -> 29
A14: Note that you multiply by 10^6 to go from grammes to tonnes by divide by 1o^3 to go from dollars to thousands of dollars | I14: =I13+0.001 -> 0.013 | J14: =MAX(NORMINV(I14,$G$2,$G$5),0) -> 0 | L14: =L13+$L$6/5 -> 5.2999271e-06 | M14: =COUNTIFS($J$2:$J$1000,"<"&L14,$J$2:J$1000,">="&L13) -> 19
I15: =I14+0.001 -> 0.014 | J15: =MAX(NORMINV(I15,$G$2,$G$5),0) -> 0 | L15: =L14+$L$6/5 -> 5.7076138e-06 | M15: =COUNTIFS($J$2:$J$1000,"<"&L15,$J$2:J$1000,">="&L14) -> 12
A16: Necessary for gamma calibration: | I16: =I15+0.001 -> 0.015 | J16: =MAX(NORMINV(I16,$G$2,$G$5),0) -> 0 | L16: =L15+$L$6/5 -> 6.1153005e-06 | M16: =COUNTIFS($J$2:$J$1000,"<"&L16,$J$2:J$1000,">="&L15) -> 8
A17: Mean distance | B17: =VLOOKUP(A17,'Fixed parameters'!B:C,2,FALSE) -> 1119.8395 | I17: =I16+0.001 -> 0.016 | J17: =MAX(NORMINV(I17,$G$2,$G$5),0) -> 0 | L17: =L16+$L$6/5 -> 6.5229872e-06 | M17: =COUNTIFS($J$2:$J$1000,"<"&L17,$J$2:J$1000,">="&L16) -> 4
A18: Discount rate | B18: =VLOOKUP(A18,'Fixed parameters'!B:C,2,FALSE) -> 0.0016515813 | I18: =I17+0.001 -> 0.017 | J18: =MAX(NORMINV(I18,$G$2,$G$5),0) -> 0 | L18: =L17+$L$6/5 -> 6.9306739e-06 | M18: =COUNTIFS($J$2:$J$1000,"<"&L18,$J$2:J$1000,">="&L17) -> 2
A19: Depreciation rate ICE cars | B19: =VLOOKUP(A19,'Fixed parameters'!B:C,2,FALSE) -> 0.0016 | I19: =I18+0.001 -> 0.018 | J19: =MAX(NORMINV(I19,$G$2,$G$5),0) -> 0 | L19: =L18+$L$6/5 -> 7.3383606e-06 | M19: =COUNTIFS($J$2:$J$1000,"<"&L19,$J$2:J$1000,">="&L18) -> 2
I20: =I19+0.001 -> 0.019 | J20: =MAX(NORMINV(I20,$G$2,$G$5),0) -> 0 | L20: =L19+$L$6/5 -> 7.7460473e-06 | M20: =COUNTIFS($J$2:$J$1000,"<"&L20,$J$2:J$1000,">="&L19) -> 0
I21: =I20+0.001 -> 0.02 | J21: =MAX(NORMINV(I21,$G$2,$G$5),0) -> 0
I22: =I21+0.001 -> 0.021 | J22: =MAX(NORMINV(I22,$G$2,$G$5),0) -> 0
I23: =I22+0.001 -> 0.022 | J23: =MAX(NORMINV(I23,$G$2,$G$5),0) -> 0
I24: =I23+0.001 -> 0.023 | J24: =MAX(NORMINV(I24,$G$2,$G$5),0) -> 0
I25: =I24+0.001 -> 0.024 | J25: =MAX(NORMINV(I25,$G$2,$G$5),0) -> 0
I26: =I25+0.001 -> 0.025 | J26: =MAX(NORMINV(I26,$G$2,$G$5),0) -> 0
I27: =I26+0.001 -> 0.026 | J27: =MAX(NORMINV(I27,$G$2,$G$5),0) -> 0
I28: =I27+0.001 -> 0.027 | J28: =MAX(NORMINV(I28,$G$2,$G$5),0) -> 0
I29: =I28+0.001 -> 0.028 | J29: =MAX(NORMINV(I29,$G$2,$G$5),0) -> 0
I30: =I29+0.001 -> 0.029 | J30: =MAX(NORMINV(I30,$G$2,$G$5),0) -> 0
I31: =I30+0.001 -> 0.03 | J31: =MAX(NORMINV(I31,$G$2,$G$5),0) -> 0
I32: =I31+0.001 -> 0.031 | J32: =MAX(NORMINV(I32,$G$2,$G$5),0) -> 0
... I1000: =I999+0.001 -> 0.999 | J1000: =MAX(NORMINV(I1000,$G$2,$G$5),0) -> 7.3266997e-06

Sheet WTP Quality
A1: Inputs | B1: Values | D1: Assumed W_s | E1: Term 1 | F1: Term 2 | G1: Term 3 | H1: Term 4 | I1: Mean beta | J1: Mean Income | L1: X-value | M1: Income | N1: Beta | P1: Bins | Q1: WTP_Q
A2: Quality elasticity | B2: =VLOOKUP(A2,'Fixed parameters'!$B:$C,2,FALSE) -> 0.5 | D2: 1e+20 | E2: =1/POW(B7,B2) -> 1.4142136 | F2: =LN(D2*(B14*(B16-B8)-1)) -> 55.283346 | G2: =1/B14 -> 1 | H2: =B16+B6*B10-B11*POW(B13*B9,B12)+(B5*(1+B4)*(1-B3)*(B17+B6*B18))/(B9*(B4-B3-B3*B4)) -> 1351996.5 | I2: =E2*(G2*F2+H2) -> 1912090 | J2: =AVERAGE(M2:M1000) -> 114296.58 | L2: 0.001 | M2: =_xlfn.LOGNORM.INV(L2,$B$19,$B$20) -> 4275.2508 | N2: =$I$2*M2/$J$2 -> 71521.511 | P2: 0 | Q2: =COUNTIFS($N$2:$N$1000,">="&P2,$N$2:$N$1000,"<"&P3) -> 21
A3: Depreciation rate ICE cars | B3: =VLOOKUP(A3,'Fixed parameters'!$B:$C,2,FALSE) -> 0.0016 | L3: =L2+0.001 -> 0.002 | M3: =_xlfn.LOGNORM.INV(L3,$B$19,$B$20) -> 5204.024 | N3: =$I$2*M3/$J$2 -> 87059.141 | P3: =P2+$I$2/10 -> 191209 | Q3: =COUNTIFS($N$2:$N$1000,">="&P3,$N$2:$N$1000,"<"&P4) -> 78
A4: Discount rate | B4: =VLOOKUP(A4,'Fixed parameters'!$B:$C,2,FALSE) -> 0.0016515813 | L4: =L3+0.001 -> 0.003 | M4: =_xlfn.LOGNORM.INV(L4,$B$19,$B$20) -> 5872.5842 | N4: =$I$2*M4/$J$2 -> 98243.615 | P4: =P3+$I$2/10 -> 382417.99 | Q4: =COUNTIFS($N$2:$N$1000,">="&P4,$N$2:$N$1000,"<"&P5) -> 100
A5: Mean distance | B5: =VLOOKUP(A5,'Fixed parameters'!$B:$C,2,FALSE) -> 1119.8395 | L5: =L4+0.001 -> 0.004 | M5: =_xlfn.LOGNORM.INV(L5,$B$19,$B$20) -> 6417.4407 | N5: =$I$2*M5/$J$2 -> 107358.63 | P5: =P4+$I$2/10 -> 573626.99 | Q5: =COUNTIFS($N$2:$N$1000,">="&P5,$N$2:$N$1000,"<"&P6) -> 97
A6: Mean WTP Emissions | B6: =VLOOKUP(A6,'Fixed parameters'!$B:$C,2,FALSE) -> 2.0384335e-06 | L6: =L5+0.001 -> 0.005 | M6: =_xlfn.LOGNORM.INV(L6,$B$19,$B$20) -> 6887.4048 | N6: =$I$2*M6/$J$2 -> 115220.75 | P6: =P5+$I$2/10 -> 764835.99 | Q6: =COUNTIFS($N$2:$N$1000,">="&P6,$N$2:$N$1000,"<"&P7) -> 88
A7: Quality: Mean | B7: =VLOOKUP(A7,'Fixed parameters'!$B:$C,2,FALSE) -> 0.5 | L7: =L6+0.001 -> 0.006 | M7: =_xlfn.LOGNORM.INV(L7,$B$19,$B$20) -> 7306.2513 | N7: =$I$2*M7/$J$2 -> 122227.71 | P7: =P6+$I$2/10 -> 956044.98 | Q7: =COUNTIFS($N$2:$N$1000,">="&P7,$N$2:$N$1000,"<"&P8) -> 77
A8: Manufacturing Cost (ICE): Mean | B8: =VLOOKUP(A8,'Fixed parameters'!$B:$C,2,FALSE) -> 29077.239 | L8: =L7+0.001 -> 0.007 | M8: =_xlfn.LOGNORM.INV(L8,$B$19,$B$20) -> 7687.5716 | N8: =$I$2*M8/$J$2 -> 128606.9 | P8: =P7+$I$2/10 -> 1147254 | Q8: =COUNTIFS($N$2:$N$1000,">="&P8,$N$2:$N$1000,"<"&P9) -> 66
A9: Fuel Efficiency (ICE): Mean | B9: =VLOOKUP(A9,'Fixed parameters'!$B:$C,2,FALSE) -> 1.9388686 | L9: =L8+0.001 -> 0.008 | M9: =_xlfn.LOGNORM.INV(L9,$B$19,$B$20) -> 8039.9543 | N9: =$I$2*M9/$J$2 -> 134501.98 | P9: =P8+$I$2/10 -> 1338463 | Q9: =COUNTIFS($N$2:$N$1000,">="&P9,$N$2:$N$1000,"<"&P10) -> 57
A10: Manufacturing Emissions (ICE) | B10: =VLOOKUP(A10,'Fixed parameters'!$B:$C,2,FALSE) -> 10000 | L10: =L9+0.001 -> 0.009 | M10: =_xlfn.LOGNORM.INV(L10,$B$19,$B$20) -> 8369.2151 | N10: =$I$2*M10/$J$2 -> 140010.25 | P10: =P9+$I$2/10 -> 1529672 | Q10: =COUNTIFS($N$2:$N$1000,">="&P10,$N$2:$N$1000,"<"&P11) -> 49
A11: WTP Range | B11: =VLOOKUP(A11,'Fixed parameters'!$B:$C,2,FALSE) -> 1173.6489 | L11: =L10+0.001 -> 0.01 | M11: =_xlfn.LOGNORM.INV(L11,$B$19,$B$20) -> 8679.4975 | N11: =$I$2*M11/$J$2 -> 145201.02 | P11: =P10+$I$2/10 -> 1720881 | Q11: =COUNTIFS($N$2:$N$1000,">="&P11,$N$2:$N$1000,"<"&P12) -> 42
A12: Range elasticity | B12: =VLOOKUP(A12,'Fixed parameters'!$B:$C,2,FALSE) -> 0.29607788 | L12: =L11+0.001 -> 0.011 | M12: =_xlfn.LOGNORM.INV(L12,$B$19,$B$20) -> 8973.8706 | N12: =$I$2*M12/$J$2 -> 150125.65 | P12: =P11+$I$2/10 -> 1912090 | Q12: =COUNTIFS($N$2:$N$1000,">="&P12,$N$2:$N$1000,"<"&P13) -> 36
A13: Average Tank Size | B13: =VLOOKUP(A13,'Fixed parameters'!$B:$C,2,FALSE) -> 469.4105 | L13: =L12+0.001 -> 0.012 | M13: =_xlfn.LOGNORM.INV(L13,$B$19,$B$20) -> 9254.6794 | N13: =$I$2*M13/$J$2 -> 154823.35 | P13: =P12+$I$2/10 -> 2103299 | Q13: =COUNTIFS($N$2:$N$1000,">="&P13,$N$2:$N$1000,"<"&P14) -> 31
A14: Consumer intensity of choice | B14: =VLOOKUP(A14,'Fixed parameters'!$B:$C,2,FALSE) -> 1 | L14: =L13+0.001 -> 0.013 | M14: =_xlfn.LOGNORM.INV(L14,$B$19,$B$20) -> 9523.7607 | N14: =$I$2*M14/$J$2 -> 159324.87 | P14: =P13+$I$2/10 -> 2294508 | Q14: =COUNTIFS($N$2:$N$1000,">="&P14,$N$2:$N$1000,"<"&P15) -> 27
... A20: Standard deviation income distribution | B20: =VLOOKUP(A20,'Fixed parameters'!$B:$C,2,FALSE) -> 0.927 | L20: =L19+0.001 -> 0.019 | M20: =_xlfn.LOGNORM.INV(L20,$B$19,$B$20) -> 10958.307 | N20: =$I$2*M20/$J$2 -> 183323.67 | P20: =P19+$I$2/10 -> 3441761.9 | Q20: =COUNTIFS($N$2:$N$1000,">="&P20,$N$2:$N$1000,"<"&P21) -> 13
L21: =L20+0.001 -> 0.02 | M21: =_xlfn.LOGNORM.INV(L21,$B$19,$B$20) -> 11174.818 | N21: =$I$2*M21/$J$2 -> 186945.73 | P21: =P20+$I$2/10 -> 3632970.9 | Q21: =COUNTIFS($N$2:$N$1000,">="&P21,$N$2:$N$1000,"<"&P22) -> 11
L22: =L21+0.001 -> 0.021 | M22: =_xlfn.LOGNORM.INV(L22,$B$19,$B$20) -> 11386.346 | N22: =$I$2*M22/$J$2 -> 190484.42 | P22: =P21+$I$2/10 -> 3824179.9 | Q22: =COUNTIFS($N$2:$N$1000,">="&P22,$N$2:$N$1000,"<"&P23) -> 10
L23: =L22+0.001 -> 0.022 | M23: =_xlfn.LOGNORM.INV(L23,$B$19,$B$20) -> 11593.284 | N23: =$I$2*M23/$J$2 -> 193946.32 | P23: =P22+$I$2/10 -> 4015388.9 | Q23: =COUNTIFS($N$2:$N$1000,">="&P23,$N$2:$N$1000,"<"&P24) -> 9
L24: =L23+0.001 -> 0.023 | M24: =_xlfn.LOGNORM.INV(L24,$B$19,$B$20) -> 11795.977 | N24: =$I$2*M24/$J$2 -> 197337.21 | P24: =P23+$I$2/10 -> 4206597.9 | Q24: =COUNTIFS($N$2:$N$1000,">="&P24,$N$2:$N$1000,"<"&P25) -> 7
L25: =L24+0.001 -> 0.024 | M25: =_xlfn.LOGNORM.INV(L25,$B$19,$B$20) -> 11994.732 | N25: =$I$2*M25/$J$2 -> 200662.23 | P25: =P24+$I$2/10 -> 4397806.9 | Q25: =COUNTIFS($N$2:$N$1000,">="&P25,$N$2:$N$1000,"<"&P26) -> 8
L26: =L25+0.001 -> 0.025 | M26: =_xlfn.LOGNORM.INV(L26,$B$19,$B$20) -> 12189.824 | N26: =$I$2*M26/$J$2 -> 203925.96 | P26: =P25+$I$2/10 -> 4589015.9 | Q26: =COUNTIFS($N$2:$N$1000,">="&P26,$N$2:$N$1000,"<"&P27) -> 6
L27: =L26+0.001 -> 0.026 | M27: =_xlfn.LOGNORM.INV(L27,$B$19,$B$20) -> 12381.496 | N27: =$I$2*M27/$J$2 -> 207132.49 | P27: =P26+$I$2/10 -> 4780224.9 | Q27: =COUNTIFS($N$2:$N$1000,">="&P27,$N$2:$N$1000,"<"&P28) -> 6
L28: =L27+0.001 -> 0.027 | M28: =_xlfn.LOGNORM.INV(L28,$B$19,$B$20) -> 12569.97 | N28: =$I$2*M28/$J$2 -> 210285.49 | P28: =P27+$I$2/10 -> 4971433.9 | Q28: =COUNTIFS($N$2:$N$1000,">="&P28,$N$2:$N$1000,"<"&P29) -> 5
L29: =L28+0.001 -> 0.028 | M29: =_xlfn.LOGNORM.INV(L29,$B$19,$B$20) -> 12755.443 | N29: =$I$2*M29/$J$2 -> 213388.31 | P29: =P28+$I$2/10 -> 5162642.9 | Q29: =COUNTIFS($N$2:$N$1000,">="&P29,$N$2:$N$1000,"<"&P30) -> 5
L30: =L29+0.001 -> 0.029 | M30: =_xlfn.LOGNORM.INV(L30,$B$19,$B$20) -> 12938.096 | N30: =$I$2*M30/$J$2 -> 216443.95 | P30: =P29+$I$2/10 -> 5353851.9 | Q30: =COUNTIFS($N$2:$N$1000,">="&P30,$N$2:$N$1000,"<"&P31) -> 4
L31: =L30+0.001 -> 0.03 | M31: =_xlfn.LOGNORM.INV(L31,$B$19,$B$20) -> 13118.093 | N31: =$I$2*M31/$J$2 -> 219455.16 | P31: =P30+$I$2/10 -> 5545060.9 | Q31: =COUNTIFS($N$2:$N$1000,">="&P31,$N$2:$N$1000,"<"&P32) -> 4
L32: =L31+0.001 -> 0.031 | M32: =_xlfn.LOGNORM.INV(L32,$B$19,$B$20) -> 13295.584 | N32: =$I$2*M32/$J$2 -> 222424.44 | P32: =P31+$I$2/10 -> 5736269.9 | Q32: =COUNTIFS($N$2:$N$1000,">="&P32,$N$2:$N$1000,"<"&P33) -> 4
... L44: =L43+0.001 -> 0.043 | M44: =_xlfn.LOGNORM.INV(L44,$B$19,$B$20) -> 15270.682 | N44: =$I$2*M44/$J$2 -> 255466.24 | P44: =P43+$I$2/10 -> 8030777.9 | Q44: =COUNTIFS($N$2:$N$1000,">="&P44,$N$2:$N$1000,"<"&P45) -> 0
L45: =L44+0.001 -> 0.044 | M45: =_xlfn.LOGNORM.INV(L45,$B$19,$B$20) -> 15424.943 | N45: =$I$2*M45/$J$2 -> 258046.91
L46: =L45+0.001 -> 0.045 | M46: =_xlfn.LOGNORM.INV(L46,$B$19,$B$20) -> 15577.919 | N46: =$I$2*M46/$J$2 -> 260606.06
L47: =L46+0.001 -> 0.046 | M47: =_xlfn.LOGNORM.INV(L47,$B$19,$B$20) -> 15729.659 | N47: =$I$2*M47/$J$2 -> 263144.55
L48: =L47+0.001 -> 0.047 | M48: =_xlfn.LOGNORM.INV(L48,$B$19,$B$20) -> 15880.211 | N48: =$I$2*M48/$J$2 -> 265663.18
L49: =L48+0.001 -> 0.048 | M49: =_xlfn.LOGNORM.INV(L49,$B$19,$B$20) -> 16029.621 | N49: =$I$2*M49/$J$2 -> 268162.69
L50: =L49+0.001 -> 0.049 | M50: =_xlfn.LOGNORM.INV(L50,$B$19,$B$20) -> 16177.931 | N50: =$I$2*M50/$J$2 -> 270643.79
L51: =L50+0.001 -> 0.05 | M51: =_xlfn.LOGNORM.INV(L51,$B$19,$B$20) -> 16325.182 | N51: =$I$2*M51/$J$2 -> 273107.17
L52: =L51+0.001 -> 0.051 | M52: =_xlfn.LOGNORM.INV(L52,$B$19,$B$20) -> 16471.411 | N52: =$I$2*M52/$J$2 -> 275553.46
L53: =L52+0.001 -> 0.052 | M53: =_xlfn.LOGNORM.INV(L53,$B$19,$B$20) -> 16616.654 | N53: =$I$2*M53/$J$2 -> 277983.27
L54: =L53+0.001 -> 0.053 | M54: =_xlfn.LOGNORM.INV(L54,$B$19,$B$20) -> 16760.947 | N54: =$I$2*M54/$J$2 -> 280397.18
L55: =L54+0.001 -> 0.054 | M55: =_xlfn.LOGNORM.INV(L55,$B$19,$B$20) -> 16904.322 | N55: =$I$2*M55/$J$2 -> 282795.72
L56: =L55+0.001 -> 0.055 | M56: =_xlfn.LOGNORM.INV(L56,$B$19,$B$20) -> 17046.81 | N56: =$I$2*M56/$J$2 -> 285179.43
...

Sheet Range WTP & Elasticity
A1: Type | B1: Input | D1: Type | E1: Proportion | F1: WTP Gasoline tank | G1: WTP Electricity tank | I1: zeta | J1: =LN(H10)/LN(H9) -> 0.29607788 | K1: =(LN(F10)-LN(G10))/(LN(F9)-LN(G9)) -> 0.29607788
A2: Source | B2: Ferguson, Mark, Moataz Mohamed, Christopher D. Higgins, Elnaz Abotalebi, and Pavlos Kanaroglou (2018). “How open are Canadian households to electric vehicles? A national latent class choice analysis with willingness-to-pay and metropolitan characterization”. In: Transportation Research Part D: Transport and Environment 58, pp. 208–224. issn: 1361-9209. doi: https://doi.org/10.1016/j.trd.2017.12.006. | D2: BEV-Oriented | E2: 0.097 | F2: 4.44 | G2: 29.86 | I2: nu_2015 | J2: =F10/POW(F9,$J$1) -> 1015.5368 | K2: =G10/POW(G9,$J$1) -> 1015.5368
D3: PHEV-Oriented | E3: 0.295 | F3: 9.69 | G3: 31.22 | I3: nu_2020 | J3: =J2/$B$9 -> 1173.6489
D4: HEV-Oriented | E4: 0.192 | F4: 21.91 | G4: 16.89 | I4: nu_model_scale | J4: =J3*'Measure conversion'!C2 -> 1173.6489
D5: ICE-Oriented | E5: 0.416 | F5: 6.24 | G5: 13.18
A7: CPI (2020 to sept 2009) | B7: 0.79557517 | F7: Gasoline | G7: Electricity | H7: Ratio
A8: km_to_miles = | B8: 1.60934 | E8: WTP_WHTAVE | F8: =SUMPRODUCT($E$2:$E$5,F2:F5) -> 10.09179 | G8: =SUMPRODUCT($E$2:$E$5,G2:G5) -> 20.83208 | H8: =F8/G8 -> 0.48443506
A9: 2015 dollars to 2020 | B9: 0.8652816 | E9: Range | F9: 700 | G9: 250 | H9: =F9/G9 -> 2.8
E10: Total WTP | F10: =F8*F9 -> 7064.253 | G10: =G8*G9 -> 5208.02 | H10: =F10/G10 -> 1.3564182
F11: =F10/40000 -> 0.17660633 | G11: =G10/40000 -> 0.1302005

Sheet Gasoline cost
A1: Type: | B1: Input | C1: Monthly California Regular Reformulated Retail Gasoline Prices (Dollars per kWh) | D1: Month | E1: Year | F1: Monthly California Regular Reformulated Retail Gasoline Prices (Dollars per Gallon) | G1: Gas 2020 Dollars per Kilowatt-Hour | H1: Model scale Dollars per KWh | M1: Week | N1: Weekly California Regular Reformulated Retail Gasoline Prices (Dollars per Gallon) | O1: Month | P1: Year
A2: Source: | B2: https://www.eia.gov/petroleum/gasdiesel/ | C2: =F2/$B$6 -> 0.041093093 | D2: Jan | E2: 2000 | F2: =AVERAGEIFS($N$2:$N$1570,$O$2:$O$1570,D2,$P$2:$P$1570,E2) -> 1.3684 | G2: 0.082089914 | H2: =G2*'Measure conversion'!$C$2 -> 0.082089914 | M2: Jan 02, 1995 | N2: 1.264 | O2: =LEFT(M2,3) -> Jan | P2: =RIGHT(M2,4) -> 1995
A3: Measure: | B3: Dollars per kilowatt hour | C3: =F3/$B$6 -> 0.043475976 | D3: Feb | E3: 2000 | F3: =AVERAGEIFS($N$2:$N$1570,$O$2:$O$1570,D3,$P$2:$P$1570,E3) -> 1.44775 | G3: 0.082089914 | H3: =G3*'Measure conversion'!$C$2 -> 0.082089914 | M3: Jan 09, 1995 | N3: 1.267 | O3: =LEFT(M3,3) -> Jan | P3: =RIGHT(M3,4) -> 1995
C4: =F4/$B$6 -> 0.052612613 | D4: Mar | E4: 2000 | F4: =AVERAGEIFS($N$2:$N$1570,$O$2:$O$1570,D4,$P$2:$P$1570,E4) -> 1.752 | G4: 0.082089914 | H4: =G4*'Measure conversion'!$C$2 -> 0.082089914 | M4: Jan 16, 1995 | N4: 1.268 | O4: =LEFT(M4,3) -> Jan | P4: =RIGHT(M4,4) -> 1995
A5: Conversions: | C5: =F5/$B$6 -> 0.05256006 | D5: Apr | E5: 2000 | F5: =AVERAGEIFS($N$2:$N$1570,$O$2:$O$1570,D5,$P$2:$P$1570,E5) -> 1.75025 | G5: 0.082089914 | H5: =G5*'Measure conversion'!$C$2 -> 0.082089914 | M5: Jan 23, 1995 | N5: 1.257 | O5: =LEFT(M5,3) -> Jan | P5: =RIGHT(M5,4) -> 1995
A6: kWh/Gallon | B6: 33.3 | C6: =F6/$B$6 -> 0.04957958 | D6: May | E6: 2000 | F6: =AVERAGEIFS($N$2:$N$1570,$O$2:$O$1570,D6,$P$2:$P$1570,E6) -> 1.651 | G6: 0.082089914 | H6: =G6*'Measure conversion'!$C$2 -> 0.082089914 | M6: Jan 30, 1995 | N6: 1.254 | O6: =LEFT(M6,3) -> Jan | P6: =RIGHT(M6,4) -> 1995
A7: Source: | B7: https://afdc.energy.gov/fuels/properties | C7: =F7/$B$6 -> 0.048693694 | D7: Jun | E7: 2000 | F7: =AVERAGEIFS($N$2:$N$1570,$O$2:$O$1570,D7,$P$2:$P$1570,E7) -> 1.6215 | G7: 0.081652854 | H7: =G7*'Measure conversion'!$C$2 -> 0.081652854 | M7: Feb 06, 1995 | N7: 1.249 | O7: =LEFT(M7,3) -> Feb | P7: =RIGHT(M7,4) -> 1995
C8: =F8/$B$6 -> 0.051363363 | D8: Jul | E8: 2000 | F8: =AVERAGEIFS($N$2:$N$1570,$O$2:$O$1570,D8,$P$2:$P$1570,E8) -> 1.7104 | G8: 0.085405875 | H8: =G8*'Measure conversion'!$C$2 -> 0.085405875 | M8: Feb 13, 1995 | N8: 1.247 | O8: =LEFT(M8,3) -> Feb | P8: =RIGHT(M8,4) -> 1995
C9: =F9/$B$6 -> 0.050322823 | D9: Aug | E9: 2000 | F9: =AVERAGEIFS($N$2:$N$1570,$O$2:$O$1570,D9,$P$2:$P$1570,E9) -> 1.67575 | G9: 0.08335649 | H9: =G9*'Measure conversion'!$C$2 -> 0.08335649 | M9: Feb 20, 1995 | N9: 1.244 | O9: =LEFT(M9,3) -> Feb | P9: =RIGHT(M9,4) -> 1995
C10: =F10/$B$6 -> 0.054827327 | D10: Sep | E10: 2000 | F10: =AVERAGEIFS($N$2:$N$1570,$O$2:$O$1570,D10,$P$2:$P$1570,E10) -> 1.82575 | G10: 0.090157609 | H10: =G10*'Measure conversion'!$C$2 -> 0.090157609 | M10: Feb 27, 1995 | N10: 1.24 | O10: =LEFT(M10,3) -> Feb | P10: =RIGHT(M10,4) -> 1995
C11: =F11/$B$6 -> 0.054414414 | D11: Oct | E11: 2000 | F11: =AVERAGEIFS($N$2:$N$1570,$O$2:$O$1570,D11,$P$2:$P$1570,E11) -> 1.812 | G11: 0.089117398 | H11: =G11*'Measure conversion'!$C$2 -> 0.089117398 | M11: Mar 06, 1995 | N11: 1.24 | O11: =LEFT(M11,3) -> Mar | P11: =RIGHT(M11,4) -> 1995
C12: =F12/$B$6 -> 0.053033033 | D12: Nov | E12: 2000 | F12: =AVERAGEIFS($N$2:$N$1570,$O$2:$O$1570,D12,$P$2:$P$1570,E12) -> 1.766 | G12: 0.08695178 | H12: =G12*'Measure conversion'!$C$2 -> 0.08695178 | M12: Mar 13, 1995 | N12: 1.229 | O12: =LEFT(M12,3) -> Mar | P12: =RIGHT(M12,4) -> 1995
C13: =F13/$B$6 -> 0.050405405 | D13: Dec | E13: 2000 | F13: =AVERAGEIFS($N$2:$N$1570,$O$2:$O$1570,D13,$P$2:$P$1570,E13) -> 1.6785 | G13: 0.08286599 | H13: =G13*'Measure conversion'!$C$2 -> 0.08286599 | M13: Mar 20, 1995 | N13: 1.227 | O13: =LEFT(M13,3) -> Mar | P13: =RIGHT(M13,4) -> 1995
C14: =F14/$B$6 -> 0.048072072 | D14: Jan | E14: 2001 | F14: =AVERAGEIFS($N$2:$N$1570,$O$2:$O$1570,D14,$P$2:$P$1570,E14) -> 1.6008 | G14: 0.078468834 | H14: =G14*'Measure conversion'!$C$2 -> 0.078468834 | M14: Mar 27, 1995 | N14: 1.22 | O14: =LEFT(M14,3) -> Mar | P14: =RIGHT(M14,4) -> 1995
C15: =F15/$B$6 -> 0.049166667 | D15: Feb | E15: 2001 | F15: =AVERAGEIFS($N$2:$N$1570,$O$2:$O$1570,D15,$P$2:$P$1570,E15) -> 1.63725 | G15: 0.079624501 | H15: =G15*'Measure conversion'!$C$2 -> 0.079624501 | M15: Apr 03, 1995 | N15: 1.216 | O15: =LEFT(M15,3) -> Apr | P15: =RIGHT(M15,4) -> 1995
C16: =F16/$B$6 -> 0.050840841 | D16: Mar | E16: 2001 | F16: =AVERAGEIFS($N$2:$N$1570,$O$2:$O$1570,D16,$P$2:$P$1570,E16) -> 1.693 | G16: 0.082001417 | H16: =G16*'Measure conversion'!$C$2 -> 0.082001417 | M16: Apr 10, 1995 | N16: 1.239 | O16: =LEFT(M16,3) -> Apr | P16: =RIGHT(M16,4) -> 1995
C17: =F17/$B$6 -> 0.053831832 | D17: Apr | E17: 2001 | F17: =AVERAGEIFS($N$2:$N$1570,$O$2:$O$1570,D17,$P$2:$P$1570,E17) -> 1.7926 | G17: 0.086384617 | H17: =G17*'Measure conversion'!$C$2 -> 0.086384617 | M17: Apr 17, 1995 | N17: 1.24 | O17: =LEFT(M17,3) -> Apr | P17: =RIGHT(M17,4) -> 1995
C18: =F18/$B$6 -> 0.058483483 | D18: May | E18: 2001 | F18: =AVERAGEIFS($N$2:$N$1570,$O$2:$O$1570,D18,$P$2:$P$1570,E18) -> 1.9475 | G18: 0.093168474 | H18: =G18*'Measure conversion'!$C$2 -> 0.093168474 | M18: Apr 24, 1995 | N18: 1.259 | O18: =LEFT(M18,3) -> Apr | P18: =RIGHT(M18,4) -> 1995
C19: =F19/$B$6 -> 0.05786036 | D19: Jun | E19: 2001 | F19: =AVERAGEIFS($N$2:$N$1570,$O$2:$O$1570,D19,$P$2:$P$1570,E19) -> 1.92675 | G19: 0.091786389 | H19: =G19*'Measure conversion'!$C$2 -> 0.091786389 | M19: May 01, 1995 | N19: 1.259 | O19: =LEFT(M19,3) -> May | P19: =RIGHT(M19,4) -> 1995
... C277: =F277/$B$6 -> 0.12964715 | D277: Dec | E277: 2022 | F277: =AVERAGEIFS($N$2:$N$1570,$O$2:$O$1570,D277,$P$2:$P$1570,E277) -> 4.31725 | G277: 0.11637687 | H277: =G277*'Measure conversion'!$C$2 -> 0.11637687 | M277: Apr 10, 2000 | N277: 1.766 | O277: =LEFT(M277,3) -> Apr | P277: =RIGHT(M277,4) -> 2000
C278: =F278/$B$6 -> 0.12808408 | D278: Jan | E278: 2023 | F278: =AVERAGEIFS($N$2:$N$1570,$O$2:$O$1570,D278,$P$2:$P$1570,E278) -> 4.2652 | M278: Apr 17, 2000 | N278: 1.741 | O278: =LEFT(M278,3) -> Apr | P278: =RIGHT(M278,4) -> 2000
C279: =F279/$B$6 -> 0.13472973 | D279: Feb | E279: 2023 | F279: =AVERAGEIFS($N$2:$N$1570,$O$2:$O$1570,D279,$P$2:$P$1570,E279) -> 4.4865 | M279: Apr 24, 2000 | N279: 1.709 | O279: =LEFT(M279,3) -> Apr | P279: =RIGHT(M279,4) -> 2000
C280: =F280/$B$6 -> 0.14058559 | D280: Mar | E280: 2023 | F280: =AVERAGEIFS($N$2:$N$1570,$O$2:$O$1570,D280,$P$2:$P$1570,E280) -> 4.6815 | M280: May 01, 2000 | N280: 1.687 | O280: =LEFT(M280,3) -> May | P280: =RIGHT(M280,4) -> 2000
C281: =F281/$B$6 -> 0.14058559 | D281: Apr | E281: 2023 | F281: =AVERAGEIFS($N$2:$N$1570,$O$2:$O$1570,D281,$P$2:$P$1570,E281) -> 4.6815 | M281: May 08, 2000 | N281: 1.671 | O281: =LEFT(M281,3) -> May | P281: =RIGHT(M281,4) -> 2000
C282: =F282/$B$6 -> 0.13913514 | D282: May | E282: 2023 | F282: =AVERAGEIFS($N$2:$N$1570,$O$2:$O$1570,D282,$P$2:$P$1570,E282) -> 4.6332 | M282: May 15, 2000 | N282: 1.646 | O282: =LEFT(M282,3) -> May | P282: =RIGHT(M282,4) -> 2000
C283: =F283/$B$6 -> 0.14035285 | D283: Jun | E283: 2023 | F283: =AVERAGEIFS($N$2:$N$1570,$O$2:$O$1570,D283,$P$2:$P$1570,E283) -> 4.67375 | M283: May 22, 2000 | N283: 1.625 | O283: =LEFT(M283,3) -> May | P283: =RIGHT(M283,4) -> 2000
C284: =F284/$B$6 -> 0.14164565 | D284: Jul | E284: 2023 | F284: =AVERAGEIFS($N$2:$N$1570,$O$2:$O$1570,D284,$P$2:$P$1570,E284) -> 4.7168 | M284: May 29, 2000 | N284: 1.626 | O284: =LEFT(M284,3) -> May | P284: =RIGHT(M284,4) -> 2000
C285: =F285/$B$6 -> 0.15082583 | D285: Aug | E285: 2023 | F285: =AVERAGEIFS($N$2:$N$1570,$O$2:$O$1570,D285,$P$2:$P$1570,E285) -> 5.0225 | M285: Jun 05, 2000 | N285: 1.613 | O285: =LEFT(M285,3) -> Jun | P285: =RIGHT(M285,4) -> 2000
C286: =F286/$B$6 -> 0.16252252 | D286: Sep | E286: 2023 | F286: =AVERAGEIFS($N$2:$N$1570,$O$2:$O$1570,D286,$P$2:$P$1570,E286) -> 5.412 | M286: Jun 12, 2000 | N286: 1.614 | O286: =LEFT(M286,3) -> Jun | P286: =RIGHT(M286,4) -> 2000
C287: =F287/$B$6 -> 0.16332132 | D287: Oct | E287: 2023 | F287: =AVERAGEIFS($N$2:$N$1570,$O$2:$O$1570,D287,$P$2:$P$1570,E287) -> 5.4386 | M287: Jun 19, 2000 | N287: 1.618 | O287: =LEFT(M287,3) -> Jun | P287: =RIGHT(M287,4) -> 2000
C288: =F288/$B$6 -> 0.14490991 | D288: Nov | E288: 2023 | F288: =AVERAGEIFS($N$2:$N$1570,$O$2:$O$1570,D288,$P$2:$P$1570,E288) -> 4.8255 | M288: Jun 26, 2000 | N288: 1.641 | O288: =LEFT(M288,3) -> Jun | P288: =RIGHT(M288,4) -> 2000
C289: =F289/$B$6 -> 0.13350601 | D289: Dec | E289: 2023 | F289: =AVERAGEIFS($N$2:$N$1570,$O$2:$O$1570,D289,$P$2:$P$1570,E289) -> 4.44575 | M289: Jul 03, 2000 | N289: 1.71 | O289: =LEFT(M289,3) -> Jul | P289: =RIGHT(M289,4) -> 2000
... C302: =F302/$B$6 -> 0.1253954 | D302: Jan | E302: 2025 | F302: =AVERAGEIFS($N$2:$N$1570,$O$2:$O$1570,D302,$P$2:$P$1570,E302) -> 4.1756667 | M302: Oct 02, 2000 | N302: 1.832 | O302: =LEFT(M302,3) -> Oct | P302: =RIGHT(M302,4) -> 2000
M303: Oct 09, 2000 | N303: 1.826 | O303: =LEFT(M303,3) -> Oct | P303: =RIGHT(M303,4) -> 2000
M304: Oct 16, 2000 | N304: 1.809 | O304: =LEFT(M304,3) -> Oct | P304: =RIGHT(M304,4) -> 2000
M305: Oct 23, 2000 | N305: 1.797 | O305: =LEFT(M305,3) -> Oct | P305: =RIGHT(M305,4) -> 2000
M306: Oct 30, 2000 | N306: 1.796 | O306: =LEFT(M306,3) -> Oct | P306: =RIGHT(M306,4) -> 2000
M307: Nov 06, 2000 | N307: 1.791 | O307: =LEFT(M307,3) -> Nov | P307: =RIGHT(M307,4) -> 2000
M308: Nov 13, 2000 | N308: 1.777 | O308: =LEFT(M308,3) -> Nov | P308: =RIGHT(M308,4) -> 2000
M309: Nov 20, 2000 | N309: 1.752 | O309: =LEFT(M309,3) -> Nov | P309: =RIGHT(M309,4) -> 2000
...

Sheet Electricity cost
A1: Type: | B1: Input | D1: Residential electricity price California, model measure dolars per kilowatt-hour | E1: Residential electricity price California, dolars per kilowatt-hour | F1: Year | G1: Month | H1: chart | I1: period | J1: stateid | K1: stateDescription | L1: sectorid | M1: sectorName | N1: price | O1: price-units
A2: Source: | B2: https://www.eia.gov/opendata/browser/electricity/retail-sales | D2: =E2*'Measure conversion'!$C$2 -> 0.1089 | E2: =N2/100 -> 0.1089 | F2: =YEAR(I2) -> 2001 | G2: =MONTH(I2) -> 1 | H2: show_chart | I2: 36892 | J2: CA | K2: California | L2: RES | M2: residential | N2: 10.89 | O2: cents per kilowatt-hour
A3: Measure: | B3: Dollars per kilowatt hour | D3: =E3*'Measure conversion'!$C$2 -> 0.1114 | E3: =N3/100 -> 0.1114 | F3: =YEAR(I3) -> 2001 | G3: =MONTH(I3) -> 2 | H3: show_chart | I3: 36923 | J3: CA | K3: California | L3: RES | M3: residential | N3: 11.14 | O3: cents per kilowatt-hour
A4: Average | B4: =AVERAGE(D2:D287) -> 0.17248706 | D4: =E4*'Measure conversion'!$C$2 -> 0.1129 | E4: =N4/100 -> 0.1129 | F4: =YEAR(I4) -> 2001 | G4: =MONTH(I4) -> 3 | H4: show_chart | I4: 36951 | J4: CA | K4: California | L4: RES | M4: residential | N4: 11.29 | O4: cents per kilowatt-hour
D5: =E5*'Measure conversion'!$C$2 -> 0.1114 | E5: =N5/100 -> 0.1114 | F5: =YEAR(I5) -> 2001 | G5: =MONTH(I5) -> 4 | H5: show_chart | I5: 36982 | J5: CA | K5: California | L5: RES | M5: residential | N5: 11.14 | O5: cents per kilowatt-hour
D6: =E6*'Measure conversion'!$C$2 -> 0.1197 | E6: =N6/100 -> 0.1197 | F6: =YEAR(I6) -> 2001 | G6: =MONTH(I6) -> 5 | H6: show_chart | I6: 37012 | J6: CA | K6: California | L6: RES | M6: residential | N6: 11.97 | O6: cents per kilowatt-hour
D7: =E7*'Measure conversion'!$C$2 -> 0.1287 | E7: =N7/100 -> 0.1287 | F7: =YEAR(I7) -> 2001 | G7: =MONTH(I7) -> 6 | H7: show_chart | I7: 37043 | J7: CA | K7: California | L7: RES | M7: residential | N7: 12.87 | O7: cents per kilowatt-hour
D8: =E8*'Measure conversion'!$C$2 -> 0.1305 | E8: =N8/100 -> 0.1305 | F8: =YEAR(I8) -> 2001 | G8: =MONTH(I8) -> 7 | H8: show_chart | I8: 37073 | J8: CA | K8: California | L8: RES | M8: residential | N8: 13.05 | O8: cents per kilowatt-hour
D9: =E9*'Measure conversion'!$C$2 -> 0.128 | E9: =N9/100 -> 0.128 | F9: =YEAR(I9) -> 2001 | G9: =MONTH(I9) -> 8 | H9: show_chart | I9: 37104 | J9: CA | K9: California | L9: RES | M9: residential | N9: 12.8 | O9: cents per kilowatt-hour
D10: =E10*'Measure conversion'!$C$2 -> 0.1287 | E10: =N10/100 -> 0.1287 | F10: =YEAR(I10) -> 2001 | G10: =MONTH(I10) -> 9 | H10: show_chart | I10: 37135 | J10: CA | K10: California | L10: RES | M10: residential | N10: 12.87 | O10: cents per kilowatt-hour
D11: =E11*'Measure conversion'!$C$2 -> 0.1249 | E11: =N11/100 -> 0.1249 | F11: =YEAR(I11) -> 2001 | G11: =MONTH(I11) -> 10 | H11: show_chart | I11: 37165 | J11: CA | K11: California | L11: RES | M11: residential | N11: 12.49 | O11: cents per kilowatt-hour
D12: =E12*'Measure conversion'!$C$2 -> 0.1212 | E12: =N12/100 -> 0.1212 | F12: =YEAR(I12) -> 2001 | G12: =MONTH(I12) -> 11 | H12: show_chart | I12: 37196 | J12: CA | K12: California | L12: RES | M12: residential | N12: 12.12 | O12: cents per kilowatt-hour
D13: =E13*'Measure conversion'!$C$2 -> 0.1226 | E13: =N13/100 -> 0.1226 | F13: =YEAR(I13) -> 2001 | G13: =MONTH(I13) -> 12 | H13: show_chart | I13: 37226 | J13: CA | K13: California | L13: RES | M13: residential | N13: 12.26 | O13: cents per kilowatt-hour
D14: =E14*'Measure conversion'!$C$2 -> 0.1303 | E14: =N14/100 -> 0.1303 | F14: =YEAR(I14) -> 2002 | G14: =MONTH(I14) -> 1 | H14: show_chart | I14: 37257 | J14: CA | K14: California | L14: RES | M14: residential | N14: 13.03 | O14: cents per kilowatt-hour
D15: =E15*'Measure conversion'!$C$2 -> 0.1258 | E15: =N15/100 -> 0.1258 | F15: =YEAR(I15) -> 2002 | G15: =MONTH(I15) -> 2 | H15: show_chart | I15: 37288 | J15: CA | K15: California | L15: RES | M15: residential | N15: 12.58 | O15: cents per kilowatt-hour
D16: =E16*'Measure conversion'!$C$2 -> 0.1258 | E16: =N16/100 -> 0.1258 | F16: =YEAR(I16) -> 2002 | G16: =MONTH(I16) -> 3 | H16: show_chart | I16: 37316 | J16: CA | K16: California | L16: RES | M16: residential | N16: 12.58 | O16: cents per kilowatt-hour
... D287: =E287*'Measure conversion'!$C$2 -> 0.3022 | E287: =N287/100 -> 0.3022 | F287: =YEAR(I287) -> 2024 | G287: =MONTH(I287) -> 10 | H287: show_chart | I287: 45566 | J287: CA | K287: California | L287: RES | M287: residential | N287: 30.22 | O287: cents per kilowatt-hour

Sheet Production emissions
A1: Source: | B1: https://www.iea.org/data-and-statistics/charts/comparative-life-cycle-greenhouse-gas-emissions-of-a-mid-size-bev-and-ice-vehicle
A4: EV_base case | B4: =5.4+1.2+1.4 -> 8 | C4: tCO2 | D4: =B4/$B$6 -> 1.3333333
A5: EV_HighGHGminerals | B5: =5.4+1.2+2.8 -> 9.4 | C5: tCO2 | D5: =B5/$B$6 -> 1.5666667
A6: ICE | B6: 6 | C6: tCO2 | D6: =B6/$B$6 -> 1
A8: Source (p.1076) | B8: https://www.ipcc.ch/report/ar6/wg3/downloads/report/IPCC_AR6_WGIII_Chapter10.pdf
B9: tCO2 | C9: kgCO2 | D9: Model scale
A10: Median EV | B10: 14 | C10: =B10*1000 -> 14000 | D10: =C10*'Measure conversion'!$C$3 -> 14000
A11: Median ICE | B11: 10 | C11: =B11*1000 -> 10000 | D11: =C11*'Measure conversion'!$C$3 -> 10000

Sheet Gasoline Emissions
A1: Type: | B1: Input | C1: kgCO2 per MJ | D1: kgCO2 per kilowatt hour | E1: Model measure per KWH
A2: Source: | C2: =B5/1000 -> 0.092 | D2: =C2/B9 -> 0.33117351 | E2: =D2*'Measure conversion'!C3 -> 0.33117351
A3: Measure: | B3: kgCO2 per kilowatt hour
A5: gCO2 per MJ | B5: 92
A6: Source: | B6: https://www.ipcc.ch/report/ar6/wg3/downloads/report/IPCC_AR6_WGIII_Chapter10.pdf
B7: Table 10.8 page 1145
A9: kWr per MJ | B9: 0.2778

Sheet Electricity emissions
A1: Type: | B1: Input | D1: Parameter | E1: GHG Intensity of Electricity Generation (In-State) | F1: GHG Intensity of Electricity Generation (Imports) | G1: GHG Intensity of Electricity Generation (Overall) | H1: EMBER Data | J1: state | K1: date | L1: emissions_intensity_gco2_per_kwh | M1: Year | N1: emissions_intensity_kgco2_per_kwh | O1: emissions_intensity_modelMeasure_per_kwh
D2: 2000 | E2: 0.26734826 | F2: 0.57492 | G2: 0.34922 | J2: California | K2: 36892 | L2: 343.27 | M2: =YEAR(K2) -> 2001 | N2: =L2/1000 -> 0.34327 | O2: =N2*'Measure conversion'!$C$3 -> 0.34327
A3: Measure: | B3: kgCO2 per kilowatt hour | D3: 2001 | E3: 0.31054469 | F3: 0.68422 | G3: 0.42216 | H3: =AVERAGEIF($M$2:$M$287,D3,$N$2:$N$287) -> 0.31102167 | J3: California | K3: 36893 | L3: 343.56 | M3: =YEAR(K3) -> 2001 | N3: =L3/1000 -> 0.34356 | O3: =N3*'Measure conversion'!$C$3 -> 0.34356
A4: Source 2: | B4: https://ember-energy.org/data/us-electricity-data-explorer/ | D4: 2002 | E4: 0.26536124 | F4: 0.57941 | G4: 0.37608 | H4: =AVERAGEIF($M$2:$M$287,D4,$N$2:$N$287) -> 0.27392083 | J4: California | K4: 36894 | L4: 325.11 | M4: =YEAR(K4) -> 2001 | N4: =L4/1000 -> 0.32511 | O4: =N4*'Measure conversion'!$C$3 -> 0.32511
A5: Average | B5: =AVERAGE(O2:O287) -> 0.27196594 | D5: 2003 | E5: 0.2466998 | F5: 0.65317 | G5: 0.3837 | H5: =AVERAGEIF($M$2:$M$287,D5,$N$2:$N$287) -> 0.26883667 | J5: California | K5: 36895 | L5: 320.78 | M5: =YEAR(K5) -> 2001 | N5: =L5/1000 -> 0.32078 | O5: =N5*'Measure conversion'!$C$3 -> 0.32078
D6: 2004 | E6: 0.24650568 | F6: 0.6356 | G6: 0.37997 | H6: =AVERAGEIF($M$2:$M$287,D6,$N$2:$N$287) -> 0.28992583 | J6: California | K6: 36896 | L6: 318.55 | M6: =YEAR(K6) -> 2001 | N6: =L6/1000 -> 0.31855 | O6: =N6*'Measure conversion'!$C$3 -> 0.31855
D7: 2005 | E7: 0.22208761 | F7: 0.62625 | G7: 0.35598 | H7: =AVERAGEIF($M$2:$M$287,D7,$N$2:$N$287) -> 0.26561333 | J7: California | K7: 36897 | L7: 288.45 | M7: =YEAR(K7) -> 2001 | N7: =L7/1000 -> 0.28845 | O7: =N7*'Measure conversion'!$C$3 -> 0.28845
D8: 2006 | E8: 0.22709168 | F8: 0.59664 | G8: 0.33608 | H8: =AVERAGEIF($M$2:$M$287,D8,$N$2:$N$287) -> 0.27257917 | J8: California | K8: 36898 | L8: 301.22 | M8: =YEAR(K8) -> 2001 | N8: =L8/1000 -> 0.30122 | O8: =N8*'Measure conversion'!$C$3 -> 0.30122
